Workbook

Sheet Control
A1: Report date | B1: 46290
A3: WK# | B3: Monday | C3: Saturday
A4: =WEEKNUM(B4,21) | B4: =$B$1-(WEEKDAY($B$1,2)-1) | C4: =B4+5
A5: =WEEKNUM(B5,21) | B5: =B4+7 | C5: =B5+5
A6: =WEEKNUM(B6,21) | B6: =B5+7 | C6: =B6+5
A7: =WEEKNUM(B7,21) | B7: =B6+7 | C7: =B7+5
A9: Tomorrow | B9: =B1+1

Sheet BookingRaw
A1: Location | B1: Pickup Date | C1: 20'RE | D1: 40'RH
A2: LCH27 | B2: 46297 | C2: 1 | D2: 0
A3: BKK27 | B3: 46301 | C3: 1 | D3: 0
A4: BKK27 | B4: 46296 | C4: 1 | D4: 0
A5: BKK27 | B5: 46297 | C5: 1 | D5: 0
A6: BKK27 | B6: 46304 | C6: 1 | D6: 0
A7: BKK27 | B7: 46294 | C7: 1 | D7: 0
A8: BKK27 | B8: 46293 | C8: 1 | D8: 0
A9: LCH27 | B9: 46304 | C9: 0 | D9: 1
A10: BKK27 | B10: 46294 | C10: 0 | D10: 1
A11: LCH27 | B11: 46291 | C11: 0 | D11: 1
A12: BKK27 | B12: 46293 | C12: 0 | D12: 1
A13: LCH27 | B13: 46298 | C13: 0 | D13: 1
... A86: BKK27 | B86: 46288 | C86: 0 | D86: 1

Sheet StockRaw
A1: Location | B1: Size/Type | C1: Move Code
A2: BKK27 | B2: 22RE | C2: IER
A3: BKK27 | B3: 22RE | C3: IED
A4: BKK27 | B4: 22RE | C4: IER
A5: BKK27 | B5: 22RE | C5: IER
A6: BKK27 | B6: 22RE | C6: IER
A7: BKK27 | B7: 22RE | C7: IER
A8: BKK27 | B8: 22RE | C8: OER
A9: BKK27 | B9: 45RE | C9: OER
A10: BKK27 | B10: 22RE | C10: OER
A11: BKK27 | B11: 45RE | C11: OER
A12: BKK27 | B12: 45RE | C12: IED
... A123: LCH27 | B123: 45RE | C123: OER

Sheet TOTAL RH
A1: ="Stock vs Booking Report - Reefer (20'RE / 40'RH) as of "&DAY(Control!$B$1)&" "&CHOOSE(MONTH(Control!$B$1),"JAN","FEB","MAR","APR","MAY","JUN","JUL","AUG","SEP","OCT","NOV","DEC")&" "&YEAR(Control!$B$1)
B2: BKK27 / BC2 | H2: LCH27 / HAST | M2: STOCK | N2: 22RE | O2: 45RE
A3: WK | C3: 20'RE | D3: 40'RH | G3: WK | I3: 20'RE | J3: 40'RH | M3: BC | N3: =C4 | O3: =D4
B4: Stock empty in yard | C4: 30 | D4: 46 | H4: Stock empty in yard | I4: 6 | J4: 40 | M4: HAST | N4: =I4 | O4: =J4
A5: =Control!$A$4 | B5: Booking Pending pick up | C5: =SUMIFS(BookingRaw!$C$2:$C$8000,BookingRaw!$A$2:$A$8000,"BKK27",BookingRaw!$B$2:$B$8000,"<"&Control!$B$1) | D5: =SUMIFS(BookingRaw!$D$2:$D$8000,BookingRaw!$A$2:$A$8000,"BKK27",BookingRaw!$B$2:$B$8000,"<"&Control!$B$1) | G5: =Control!$A$4 | H5: Booking Pending pick up | I5: =SUMIFS(BookingRaw!$C$2:$C$8000,BookingRaw!$A$2:$A$8000,"LCH27",BookingRaw!$B$2:$B$8000,"<"&Control!$B$1) | J5: =SUMIFS(BookingRaw!$D$2:$D$8000,BookingRaw!$A$2:$A$8000,"LCH27",BookingRaw!$B$2:$B$8000,"<"&Control!$B$1) | M5: TOTAL | N5: =SUM(N3:N4) | O5: =SUM(O3:O4)
A6: =Control!$A$4 | B6: ="Booking on "&IF(Control!$B$1=Control!$C$4,DAY(Control!$B$1)&" "&CHOOSE(MONTH(Control!$B$1),"JAN","FEB","MAR","APR","MAY","JUN","JUL","AUG","SEP","OCT","NOV","DEC"),IF(MONTH(Control!$B$1)=MONTH(Control!$C$4),DAY(Control!$B$1)&"-"&DAY(Control!$C$4)&" "&CHOOSE(MONTH(Control!$C$4),"JAN","FEB","MAR","APR","MAY","JUN","JUL","AUG","SEP","OCT","NOV","DEC"),DAY(Control!$B$1)&" "&CHOOSE(MONTH(Control!$B$1),"JAN","FEB","MAR","APR","MAY","JUN","JUL","AUG","SEP","OCT","NOV","DEC")&"-"&DAY(Control!$C$4)&" "&CHOOSE(MONTH(Control!$C$4),"JAN","FEB","MAR","APR","MAY","JUN","JUL","AUG","SEP","OCT","NOV","DEC"))) | C6: =SUMIFS(BookingRaw!$C$2:$C$8000,BookingRaw!$A$2:$A$8000,"BKK27",BookingRaw!$B$2:$B$8000,">="&Control!$B$1,BookingRaw!$B$2:$B$8000,"<="&Control!$C$4) | D6: =SUMIFS(BookingRaw!$D$2:$D$8000,BookingRaw!$A$2:$A$8000,"BKK27",BookingRaw!$B$2:$B$8000,">="&Control!$B$1,BookingRaw!$B$2:$B$8000,"<="&Control!$C$4) | G6: =Control!$A$4 | H6: ="Booking on "&IF(Control!$B$1=Control!$C$4,DAY(Control!$B$1)&" "&CHOOSE(MONTH(Control!$B$1),"JAN","FEB","MAR","APR","MAY","JUN","JUL","AUG","SEP","OCT","NOV","DEC"),IF(MONTH(Control!$B$1)=MONTH(Control!$C$4),DAY(Control!$B$1)&"-"&DAY(Control!$C$4)&" "&CHOOSE(MONTH(Control!$C$4),"JAN","FEB","MAR","APR","MAY","JUN","JUL","AUG","SEP","OCT","NOV","DEC"),DAY(Control!$B$1)&" "&CHOOSE(MONTH(Control!$B$1),"JAN","FEB","MAR","APR","MAY","JUN","JUL","AUG","SEP","OCT","NOV","DEC")&"-"&DAY(Control!$C$4)&" "&CHOOSE(MONTH(Control!$C$4),"JAN","FEB","MAR","APR","MAY","JUN","JUL","AUG","SEP","OCT","NOV","DEC"))) | I6: =SUMIFS(BookingRaw!$C$2:$C$8000,BookingRaw!$A$2:$A$8000,"LCH27",BookingRaw!$B$2:$B$8000,">="&Control!$B$1,BookingRaw!$B$2:$B$8000,"<="&Control!$C$4) | J6: =SUMIFS(BookingRaw!$D$2:$D$8000,BookingRaw!$A$2:$A$8000,"LCH27",BookingRaw!$B$2:$B$8000,">="&Control!$B$1,BookingRaw!$B$2:$B$8000,"<="&Control!$C$4)
B7: ="AV Balance till "&DAY(Control!$C$4)&" "&CHOOSE(MONTH(Control!$C$4),"JAN","FEB","MAR","APR","MAY","JUN","JUL","AUG","SEP","OCT","NOV","DEC") | C7: =C4-C5-C6 | D7: =D4-D5-D6 | H7: ="AV Balance till "&DAY(Control!$C$4)&" "&CHOOSE(MONTH(Control!$C$4),"JAN","FEB","MAR","APR","MAY","JUN","JUL","AUG","SEP","OCT","NOV","DEC") | I7: =I4-I5-I6 | J7: =J4-J5-J6 | M7: BOOKING | N7: 22RE | O7: 45RE
A8: =Control!$A$5 | B8: ="Booking on "&IF(Control!$B5=Control!$C5,DAY(Control!$B5)&" "&CHOOSE(MONTH(Control!$B5),"JAN","FEB","MAR","APR","MAY","JUN","JUL","AUG","SEP","OCT","NOV","DEC"),IF(MONTH(Control!$B5)=MONTH(Control!$C5),DAY(Control!$B5)&"-"&DAY(Control!$C5)&" "&CHOOSE(MONTH(Control!$C5),"JAN","FEB","MAR","APR","MAY","JUN","JUL","AUG","SEP","OCT","NOV","DEC"),DAY(Control!$B5)&" "&CHOOSE(MONTH(Control!$B5),"JAN","FEB","MAR","APR","MAY","JUN","JUL","AUG","SEP","OCT","NOV","DEC")&"-"&DAY(Control!$C5)&" "&CHOOSE(MONTH(Control!$C5),"JAN","FEB","MAR","APR","MAY","JUN","JUL","AUG","SEP","OCT","NOV","DEC"))) | C8: =SUMIFS(BookingRaw!$C$2:$C$8000,BookingRaw!$A$2:$A$8000,"BKK27",BookingRaw!$B$2:$B$8000,">="&Control!$B5,BookingRaw!$B$2:$B$8000,"<="&Control!$C5) | D8: =SUMIFS(BookingRaw!$D$2:$D$8000,BookingRaw!$A$2:$A$8000,"BKK27",BookingRaw!$B$2:$B$8000,">="&Control!$B5,BookingRaw!$B$2:$B$8000,"<="&Control!$C5) | G8: =Control!$A$5 | H8: ="Booking on "&IF(Control!$B5=Control!$C5,DAY(Control!$B5)&" "&CHOOSE(MONTH(Control!$B5),"JAN","FEB","MAR","APR","MAY","JUN","JUL","AUG","SEP","OCT","NOV","DEC"),IF(MONTH(Control!$B5)=MONTH(Control!$C5),DAY(Control!$B5)&"-"&DAY(Control!$C5)&" "&CHOOSE(MONTH(Control!$C5),"JAN","FEB","MAR","APR","MAY","JUN","JUL","AUG","SEP","OCT","NOV","DEC"),DAY(Control!$B5)&" "&CHOOSE(MONTH(Control!$B5),"JAN","FEB","MAR","APR","MAY","JUN","JUL","AUG","SEP","OCT","NOV","DEC")&"-"&DAY(Control!$C5)&" "&CHOOSE(MONTH(Control!$C5),"JAN","FEB","MAR","APR","MAY","JUN","JUL","AUG","SEP","OCT","NOV","DEC"))) | I8: =SUMIFS(BookingRaw!$C$2:$C$8000,BookingRaw!$A$2:$A$8000,"LCH27",BookingRaw!$B$2:$B$8000,">="&Control!$B5,BookingRaw!$B$2:$B$8000,"<="&Control!$C5) | J8: =SUMIFS(BookingRaw!$D$2:$D$8000,BookingRaw!$A$2:$A$8000,"LCH27",BookingRaw!$B$2:$B$8000,">="&Control!$B5,BookingRaw!$B$2:$B$8000,"<="&Control!$C5) | M8: BC | N8: =C5+C6+C8+C10+C12 | O8: =D5+D6+D8+D10+D12
B9: ="AV Balance till "&DAY(Control!$C5)&" "&CHOOSE(MONTH(Control!$C5),"JAN","FEB","MAR","APR","MAY","JUN","JUL","AUG","SEP","OCT","NOV","DEC") | C9: =C7-C8 | D9: =D7-D8 | H9: ="AV Balance till "&DAY(Control!$C5)&" "&CHOOSE(MONTH(Control!$C5),"JAN","FEB","MAR","APR","MAY","JUN","JUL","AUG","SEP","OCT","NOV","DEC") | I9: =I7-I8 | J9: =J7-J8 | M9: HAST | N9: =I5+I6+I8+I10+I12 | O9: =J5+J6+J8+J10+J12
A10: =Control!$A$6 | B10: ="Booking on "&IF(Control!$B6=Control!$C6,DAY(Control!$B6)&" "&CHOOSE(MONTH(Control!$B6),"JAN","FEB","MAR","APR","MAY","JUN","JUL","AUG","SEP","OCT","NOV","DEC"),IF(MONTH(Control!$B6)=MONTH(Control!$C6),DAY(Control!$B6)&"-"&DAY(Control!$C6)&" "&CHOOSE(MONTH(Control!$C6),"JAN","FEB","MAR","APR","MAY","JUN","JUL","AUG","SEP","OCT","NOV","DEC"),DAY(Control!$B6)&" "&CHOOSE(MONTH(Control!$B6),"JAN","FEB","MAR","APR","MAY","JUN","JUL","AUG","SEP","OCT","NOV","DEC")&"-"&DAY(Control!$C6)&" "&CHOOSE(MONTH(Control!$C6),"JAN","FEB","MAR","APR","MAY","JUN","JUL","AUG","SEP","OCT","NOV","DEC"))) | C10: =SUMIFS(BookingRaw!$C$2:$C$8000,BookingRaw!$A$2:$A$8000,"BKK27",BookingRaw!$B$2:$B$8000,">="&Control!$B6,BookingRaw!$B$2:$B$8000,"<="&Control!$C6) | D10: =SUMIFS(BookingRaw!$D$2:$D$8000,BookingRaw!$A$2:$A$8000,"BKK27",BookingRaw!$B$2:$B$8000,">="&Control!$B6,BookingRaw!$B$2:$B$8000,"<="&Control!$C6) | G10: =Control!$A$6 | H10: ="Booking on "&IF(Control!$B6=Control!$C6,DAY(Control!$B6)&" "&CHOOSE(MONTH(Control!$B6),"JAN","FEB","MAR","APR","MAY","JUN","JUL","AUG","SEP","OCT","NOV","DEC"),IF(MONTH(Control!$B6)=MONTH(Control!$C6),DAY(Control!$B6)&"-"&DAY(Control!$C6)&" "&CHOOSE(MONTH(Control!$C6),"JAN","FEB","MAR","APR","MAY","JUN","JUL","AUG","SEP","OCT","NOV","DEC"),DAY(Control!$B6)&" "&CHOOSE(MONTH(Control!$B6),"JAN","FEB","MAR","APR","MAY","JUN","JUL","AUG","SEP","OCT","NOV","DEC")&"-"&DAY(Control!$C6)&" "&CHOOSE(MONTH(Control!$C6),"JAN","FEB","MAR","APR","MAY","JUN","JUL","AUG","SEP","OCT","NOV","DEC"))) | I10: =SUMIFS(BookingRaw!$C$2:$C$8000,BookingRaw!$A$2:$A$8000,"LCH27",BookingRaw!$B$2:$B$8000,">="&Control!$B6,BookingRaw!$B$2:$B$8000,"<="&Control!$C6) | J10: =SUMIFS(BookingRaw!$D$2:$D$8000,BookingRaw!$A$2:$A$8000,"LCH27",BookingRaw!$B$2:$B$8000,">="&Control!$B6,BookingRaw!$B$2:$B$8000,"<="&Control!$C6) | M10: TOTAL | N10: =SUM(N8:N9) | O10: =SUM(O8:O9)
B11: ="AV Balance till "&DAY(Control!$C6)&" "&CHOOSE(MONTH(Control!$C6),"JAN","FEB","MAR","APR","MAY","JUN","JUL","AUG","SEP","OCT","NOV","DEC") | C11: =C9-C10 | D11: =D9-D10 | H11: ="AV Balance till "&DAY(Control!$C6)&" "&CHOOSE(MONTH(Control!$C6),"JAN","FEB","MAR","APR","MAY","JUN","JUL","AUG","SEP","OCT","NOV","DEC") | I11: =I9-I10 | J11: =J9-J10
A12: =Control!$A$7 | B12: ="Booking on "&IF(Control!$B7=Control!$C7,DAY(Control!$B7)&" "&CHOOSE(MONTH(Control!$B7),"JAN","FEB","MAR","APR","MAY","JUN","JUL","AUG","SEP","OCT","NOV","DEC"),IF(MONTH(Control!$B7)=MONTH(Control!$C7),DAY(Control!$B7)&"-"&DAY(Control!$C7)&" "&CHOOSE(MONTH(Control!$C7),"JAN","FEB","MAR","APR","MAY","JUN","JUL","AUG","SEP","OCT","NOV","DEC"),DAY(Control!$B7)&" "&CHOOSE(MONTH(Control!$B7),"JAN","FEB","MAR","APR","MAY","JUN","JUL","AUG","SEP","OCT","NOV","DEC")&"-"&DAY(Control!$C7)&" "&CHOOSE(MONTH(Control!$C7),"JAN","FEB","MAR","APR","MAY","JUN","JUL","AUG","SEP","OCT","NOV","DEC"))) | C12: =SUMIFS(BookingRaw!$C$2:$C$8000,BookingRaw!$A$2:$A$8000,"BKK27",BookingRaw!$B$2:$B$8000,">="&Control!$B7,BookingRaw!$B$2:$B$8000,"<="&Control!$C7) | D12: =SUMIFS(BookingRaw!$D$2:$D$8000,BookingRaw!$A$2:$A$8000,"BKK27",BookingRaw!$B$2:$B$8000,">="&Control!$B7,BookingRaw!$B$2:$B$8000,"<="&Control!$C7) | G12: =Control!$A$7 | H12: ="Booking on "&IF(Control!$B7=Control!$C7,DAY(Control!$B7)&" "&CHOOSE(MONTH(Control!$B7),"JAN","FEB","MAR","APR","MAY","JUN","JUL","AUG","SEP","OCT","NOV","DEC"),IF(MONTH(Control!$B7)=MONTH(Control!$C7),DAY(Control!$B7)&"-"&DAY(Control!$C7)&" "&CHOOSE(MONTH(Control!$C7),"JAN","FEB","MAR","APR","MAY","JUN","JUL","AUG","SEP","OCT","NOV","DEC"),DAY(Control!$B7)&" "&CHOOSE(MONTH(Control!$B7),"JAN","FEB","MAR","APR","MAY","JUN","JUL","AUG","SEP","OCT","NOV","DEC")&"-"&DAY(Control!$C7)&" "&CHOOSE(MONTH(Control!$C7),"JAN","FEB","MAR","APR","MAY","JUN","JUL","AUG","SEP","OCT","NOV","DEC"))) | I12: =SUMIFS(BookingRaw!$C$2:$C$8000,BookingRaw!$A$2:$A$8000,"LCH27",BookingRaw!$B$2:$B$8000,">="&Control!$B7,BookingRaw!$B$2:$B$8000,"<="&Control!$C7) | J12: =SUMIFS(BookingRaw!$D$2:$D$8000,BookingRaw!$A$2:$A$8000,"LCH27",BookingRaw!$B$2:$B$8000,">="&Control!$B7,BookingRaw!$B$2:$B$8000,"<="&Control!$C7) | M12: BALANCE | N12: 22RE | O12: 45RE
B13: ="AV Balance till "&DAY(Control!$C7)&" "&CHOOSE(MONTH(Control!$C7),"JAN","FEB","MAR","APR","MAY","JUN","JUL","AUG","SEP","OCT","NOV","DEC") | C13: =C11-C12 | D13: =D11-D12 | H13: ="AV Balance till "&DAY(Control!$C7)&" "&CHOOSE(MONTH(Control!$C7),"JAN","FEB","MAR","APR","MAY","JUN","JUL","AUG","SEP","OCT","NOV","DEC") | I13: =I11-I12 | J13: =J11-J12 | M13: BC | N13: =C13 | O13: =D13
M14: HAST | N14: =I13 | O14: =J13
A15: Remarks: | B15: AV = stock with move code IED / IEP / IER (available) | DMG = move code OER (damaged) | M15: TOTAL | N15: =SUM(N13:N14) | O15: =SUM(O13:O14)
C16: 20'RE | D16: 40'RH | I16: 20'RE | J16: 40'RH
B17: AV | C17: =COUNTIFS(StockRaw!$A$2:$A$123,"BKK27",StockRaw!$B$2:$B$123,"22RE",StockRaw!$C$2:$C$123,"IED")+COUNTIFS(StockRaw!$A$2:$A$123,"BKK27",StockRaw!$B$2:$B$123,"22RE",StockRaw!$C$2:$C$123,"IEP")+COUNTIFS(StockRaw!$A$2:$A$123,"BKK27",StockRaw!$B$2:$B$123,"22RE",StockRaw!$C$2:$C$123,"IER") | D17: =COUNTIFS(StockRaw!$A$2:$A$123,"BKK27",StockRaw!$B$2:$B$123,"45RE",StockRaw!$C$2:$C$123,"IED")+COUNTIFS(StockRaw!$A$2:$A$123,"BKK27",StockRaw!$B$2:$B$123,"45RE",StockRaw!$C$2:$C$123,"IEP")+COUNTIFS(StockRaw!$A$2:$A$123,"BKK27",StockRaw!$B$2:$B$123,"45RE",StockRaw!$C$2:$C$123,"IER") | H17: AV | I17: =COUNTIFS(StockRaw!$A$2:$A$123,"LCH27",StockRaw!$B$2:$B$123,"22RE",StockRaw!$C$2:$C$123,"IED")+COUNTIFS(StockRaw!$A$2:$A$123,"LCH27",StockRaw!$B$2:$B$123,"22RE",StockRaw!$C$2:$C$123,"IEP")+COUNTIFS(StockRaw!$A$2:$A$123,"LCH27",StockRaw!$B$2:$B$123,"22RE",StockRaw!$C$2:$C$123,"IER") | J17: =COUNTIFS(StockRaw!$A$2:$A$123,"LCH27",StockRaw!$B$2:$B$123,"45RE",StockRaw!$C$2:$C$123,"IED")+COUNTIFS(StockRaw!$A$2:$A$123,"LCH27",StockRaw!$B$2:$B$123,"45RE",StockRaw!$C$2:$C$123,"IEP")+COUNTIFS(StockRaw!$A$2:$A$123,"LCH27",StockRaw!$B$2:$B$123,"45RE",StockRaw!$C$2:$C$123,"IER")
B18: DMG | C18: =COUNTIFS(StockRaw!$A$2:$A$123,"BKK27",StockRaw!$B$2:$B$123,"22RE",StockRaw!$C$2:$C$123,"OER") | D18: =COUNTIFS(StockRaw!$A$2:$A$123,"BKK27",StockRaw!$B$2:$B$123,"45RE",StockRaw!$C$2:$C$123,"OER") | H18: DMG | I18: =COUNTIFS(StockRaw!$A$2:$A$123,"LCH27",StockRaw!$B$2:$B$123,"22RE",StockRaw!$C$2:$C$123,"OER") | J18: =COUNTIFS(StockRaw!$A$2:$A$123,"LCH27",StockRaw!$B$2:$B$123,"45RE",StockRaw!$C$2:$C$123,"OER")
B21: BKK / BC2 (BKK27) | H21: LCH / HAST (LCH27)
B22: YEAR BUILT 5 YEARS FOR DURIAN SEASON | C22: CARRIER | D22: DAIKIN | E22: THERMO KING | H22: YEAR BUILT 5 YEARS FOR DURIAN SEASON | I22: CARRIER | J22: DAIKIN | K22: THERMO KING
C23: 45RE | D23: 45RE | E23: 45RE | I23: 45RE | J23: 45RE | K23: 45RE
B24: 2026 | C24: 0 | D24: 0 | E24: 0 | H24: 2026 | I24: 0 | J24: 0 | K24: 0
B25: 2025 | C25: 7 | D25: 0 | E25: 0 | H25: 2025 | I25: 10 | J25: 0 | K25: 0
B26: 2024 | C26: 0 | D26: 0 | E26: 0 | H26: 2024 | I26: 0 | J26: 0 | K26: 0
B27: 2023 | C27: 1 | D27: 0 | E27: 0 | H27: 2023 | I27: 3 | J27: 0 | K27: 0
B28: 2022 | C28: 0 | D28: 0 | E28: 0 | H28: 2022 | I28: 0 | J28: 0 | K28: 0
B29: 2021 | C29: 10 | D29: 0 | E29: 0 | H29: 2021 | I29: 7 | J29: 0 | K29: 0
B30: TOTAL | C30: 18 | D30: 0 | E30: 0 | H30: TOTAL | I30: 20 | J30: 0 | K30: 0
D31: OVER 5 Y | E31: 28 | J31: OVER 5 Y | K31: 20
B34: BKK27 / BC2 — Stock by Built Year x Brand x Size | J34: LCH27 / HAST — Stock by Built Year x Brand x Size
B35: YEAR BUILT | C35: CARRIER | E35: DAIKIN | G35: THERMO KING | J35: YEAR BUILT | K35: CARRIER | M35: DAIKIN | O35: THERMO KING
C36: 20'RE | D36: 40'RH | E36: 20'RE | F36: 40'RH | G36: 20'RE | H36: 40'RH | K36: 20'RE | L36: 40'RH | M36: 20'RE | N36: 40'RH | O36: 20'RE | P36: 40'RH
B37: 2026 | J37: 2026
B38: 2025 | D38: 7 | E38: 2 | J38: 2025 | L38: 10
B39: 2024 | J39: 2024
B40: 2023 | D40: 1 | J40: 2023 | L40: 3
B41: 2022 | J41: 2022
B42: 2021 | C42: 7 | D42: 10 | J42: 2021 | K42: 1 | L42: 7
B43: 2020 | C43: 1 | D43: 11 | J43: 2020 | L43: 3
B44: 2019 | C44: 4 | D44: 4 | J44: 2019 | L44: 8
...

Sheet Dashboard
B1: ='TOTAL RH'!A1
B4: SHORTFALL ALERT | F4: COMBINED 40'RH STOCK | J4: COMBINED 40'RH BOOKING | N4: COMBINED 40'RH BALANCE
B5: =MIN('TOTAL RH'!D13,'TOTAL RH'!J13) | F5: ='TOTAL RH'!O5 | J5: ='TOTAL RH'!O10 | N5: ='TOTAL RH'!O15
B6: ="BKK27/LCH27 40'RH, worse "&'TOTAL RH'!B13 | F6: BKK27 + LCH27 | J6: pending + all weeks | N6: ="pending + all weeks, both depots, "&'TOTAL RH'!B13
B8: DETAIL BY DEPOT
B9: ='TOTAL RH'!B2 | H9: ='TOTAL RH'!H2
C10: 20'RE | D10: 40'RH | I10: 20'RE | J10: 40'RH
B11: ='TOTAL RH'!B4 | C11: ='TOTAL RH'!C4 | D11: ='TOTAL RH'!D4 | H11: ='TOTAL RH'!H4 | I11: ='TOTAL RH'!I4 | J11: ='TOTAL RH'!J4
B12: ='TOTAL RH'!B5 | C12: ='TOTAL RH'!C5 | D12: ='TOTAL RH'!D5 | H12: ='TOTAL RH'!H5 | I12: ='TOTAL RH'!I5 | J12: ='TOTAL RH'!J5
B13: ='TOTAL RH'!B6 | C13: ='TOTAL RH'!C6 | D13: ='TOTAL RH'!D6 | H13: ='TOTAL RH'!H6 | I13: ='TOTAL RH'!I6 | J13: ='TOTAL RH'!J6
B14: ='TOTAL RH'!B7 | C14: ='TOTAL RH'!C7 | D14: ='TOTAL RH'!D7 | H14: ='TOTAL RH'!H7 | I14: ='TOTAL RH'!I7 | J14: ='TOTAL RH'!J7
B15: ='TOTAL RH'!B8 | C15: ='TOTAL RH'!C8 | D15: ='TOTAL RH'!D8 | H15: ='TOTAL RH'!H8 | I15: ='TOTAL RH'!I8 | J15: ='TOTAL RH'!J8
B16: ='TOTAL RH'!B9 | C16: ='TOTAL RH'!C9 | D16: ='TOTAL RH'!D9 | H16: ='TOTAL RH'!H9 | I16: ='TOTAL RH'!I9 | J16: ='TOTAL RH'!J9
B17: ='TOTAL RH'!B10 | C17: ='TOTAL RH'!C10 | D17: ='TOTAL RH'!D10 | H17: ='TOTAL RH'!H10 | I17: ='TOTAL RH'!I10 | J17: ='TOTAL RH'!J10
B18: ='TOTAL RH'!B11 | C18: ='TOTAL RH'!C11 | D18: ='TOTAL RH'!D11 | H18: ='TOTAL RH'!H11 | I18: ='TOTAL RH'!I11 | J18: ='TOTAL RH'!J11
B19: ='TOTAL RH'!B12 | C19: ='TOTAL RH'!C12 | D19: ='TOTAL RH'!D12 | H19: ='TOTAL RH'!H12 | I19: ='TOTAL RH'!I12 | J19: ='TOTAL RH'!J12
B20: ='TOTAL RH'!B13 | C20: ='TOTAL RH'!C13 | D20: ='TOTAL RH'!D13 | H20: ='TOTAL RH'!H13 | I20: ='TOTAL RH'!I13 | J20: ='TOTAL RH'!J13
B23: REMARKS (AV = move code IED/IEP/IER, DMG = move code OER)
B24: ='TOTAL RH'!B2 | H24: ='TOTAL RH'!H2
C25: 20'RE | D25: 40'RH | I25: 20'RE | J25: 40'RH
B26: AV | C26: ='TOTAL RH'!C17 | D26: ='TOTAL RH'!D17 | H26: AV | I26: ='TOTAL RH'!I17 | J26: ='TOTAL RH'!J17
B27: DMG | C27: ='TOTAL RH'!C18 | D27: ='TOTAL RH'!D18 | H27: DMG | I27: ='TOTAL RH'!I18 | J27: ='TOTAL RH'!J18
B30: RF SEASONAL — build year
B31: BKK27 2020-26 BUILT | F31: LCH27 2020-26 BUILT | J31: PEAK BUILD YEAR
B32: =SUM('TOTAL RH'!D37:D43)+SUM('TOTAL RH'!F37:F43)+SUM('TOTAL RH'!H37:H43) | F32: =SUM('TOTAL RH'!L37:L43)+SUM('TOTAL RH'!N37:N43)+SUM('TOTAL RH'!P37:P43) | J32: ="2025 / 2021"
B33: of 40'RH on hand | F33: of 40'RH on hand | J33: 17 units across both depots
B35: BKK27 DURIAN (2021-2026) | F35: BKK27 NON DURIAN (≤ 2020) | J35: LCH27 DURIAN (2021-2026) | N35: LCH27 NON DURIAN (≤ 2020)
B36: ='TOTAL RH'!B59 | F36: ='TOTAL RH'!F59 | J36: ='TOTAL RH'!J59 | N36: ='TOTAL RH'!N59
B37: 40'RH stock | F37: 40'RH stock | J37: 40'RH stock | N37: 40'RH stock
B39: BKK27 current mix | H39: LCH27 current mix
C40: 22RE | D40: 45RE | I40: 22RE | J40: 45RE
B41: CARRIER | C41: ='TOTAL RH'!C54 | D41: ='TOTAL RH'!D54 | H41: CARRIER | I41: ='TOTAL RH'!K54 | J41: ='TOTAL RH'!L54
B42: DAIKIN | C42: ='TOTAL RH'!E54 | D42: ='TOTAL RH'!F54 | H42: DAIKIN | I42: ='TOTAL RH'!M54 | J42: ='TOTAL RH'!N54
B43: THERMO KING | C43: ='TOTAL RH'!G54 | D43: ='TOTAL RH'!H54 | H43: THERMO KING | I43: ='TOTAL RH'!O54 | J43: ='TOTAL RH'!P54
B45: Full 2010-2026 Year x Brand x Size breakdown is on the TOTAL RH sheet.
