Workbook

Sheet Control
A1: Report date | B1: 46289
A3: WK# | B3: Monday | C3: Saturday
A4: =WEEKNUM(B4,21) | B4: =$B$1-(WEEKDAY($B$1,2)-1) | C4: =B4+5
A5: =WEEKNUM(B5,21) | B5: =B4+7 | C5: =B5+5
A6: =WEEKNUM(B6,21) | B6: =B5+7 | C6: =B6+5
A7: =WEEKNUM(B7,21) | B7: =B6+7 | C7: =B7+5
A9: Tomorrow | B9: =B1+1

Sheet BookingRaw
A1: Location | B1: Pickup Date | C1: 20'RE | D1: 40'RH
A2: BKK27 | B2: 46289 | C2: 1 | D2: 0
A3: LCH27 | B3: 46297 | C3: 1 | D3: 0
A4: BKK27 | B4: 46301 | C4: 1 | D4: 0
A5: BKK27 | B5: 46296 | C5: 1 | D5: 0
A6: LCH27 | B6: 46297 | C6: 1 | D6: 0
A7: BKK27 | B7: 46297 | C7: 1 | D7: 0
A8: BKK27 | B8: 46289 | C8: 1 | D8: 0
A9: BKK27 | B9: 46304 | C9: 1 | D9: 0
A10: BKK27 | B10: 46294 | C10: 1 | D10: 0
A11: BKK27 | B11: 46293 | C11: 1 | D11: 0
A12: LCH27 | B12: 46289 | C12: 0 | D12: 1
A13: BKK27 | B13: 46294 | C13: 0 | D13: 1
... A87: LCH27 | B87: 46286 | C87: 0 | D87: 1

Sheet StockRaw
A1: Location | B1: Size/Type | C1: Move Code
A2: BKK27 | B2: 22RE | C2: IER
A3: BKK27 | B3: 22RE | C3: IER
A4: BKK27 | B4: 22RE | C4: IER
A5: BKK27 | B5: 22RE | C5: IER
A6: BKK27 | B6: 22RE | C6: IER
A7: BKK27 | B7: 22RE | C7: OER
A8: BKK27 | B8: 22RE | C8: IER
A9: BKK27 | B9: 45RE | C9: IED
A10: BKK27 | B10: 22RE | C10: IED
A11: BKK27 | B11: 45RE | C11: IED
A12: BKK27 | B12: 22RE | C12: IED
... A108: LCH27 | B108: 45RE | C108: OER

Sheet TOTAL RH
A1: ="Stock vs Booking Report - Reefer (20'RE / 40'RH) as of "&DAY(Control!$B$1)&" "&CHOOSE(MONTH(Control!$B$1),"JAN","FEB","MAR","APR","MAY","JUN","JUL","AUG","SEP","OCT","NOV","DEC")&" "&YEAR(Control!$B$1)
B2: BKK27 / BC2 | H2: LCH27 / HAST | M2: STOCK | N2: 22RE | O2: 45RE
A3: WK | C3: 20'RE | D3: 40'RH | G3: WK | I3: 20'RE | J3: 40'RH | M3: BC | N3: =C4 | O3: =D4
B4: Stock empty in yard | C4: 30 | D4: 33 | H4: Stock empty in yard | I4: 6 | J4: 38 | M4: HAST | N4: =I4 | O4: =J4
A5: =Control!$A$4 | B5: Booking Pending pick up | C5: =SUMIFS(BookingRaw!$C$2:$C$8000,BookingRaw!$A$2:$A$8000,"BKK27",BookingRaw!$B$2:$B$8000,"<"&Control!$B$1) | D5: =SUMIFS(BookingRaw!$D$2:$D$8000,BookingRaw!$A$2:$A$8000,"BKK27",BookingRaw!$B$2:$B$8000,"<"&Control!$B$1) | G5: =Control!$A$4 | H5: Booking Pending pick up | I5: =SUMIFS(BookingRaw!$C$2:$C$8000,BookingRaw!$A$2:$A$8000,"LCH27",BookingRaw!$B$2:$B$8000,"<"&Control!$B$1) | J5: =SUMIFS(BookingRaw!$D$2:$D$8000,BookingRaw!$A$2:$A$8000,"LCH27",BookingRaw!$B$2:$B$8000,"<"&Control!$B$1) | M5: TOTAL | N5: =SUM(N3:N4) | O5: =SUM(O3:O4)
A6: =Control!$A$4 | B6: ="Booking on "&DAY(Control!$B$1)&" "&CHOOSE(MONTH(Control!$B$1),"JAN","FEB","MAR","APR","MAY","JUN","JUL","AUG","SEP","OCT","NOV","DEC") | C6: =SUMIFS(BookingRaw!$C$2:$C$8000,BookingRaw!$A$2:$A$8000,"BKK27",BookingRaw!$B$2:$B$8000,"="&Control!$B$1) | D6: =SUMIFS(BookingRaw!$D$2:$D$8000,BookingRaw!$A$2:$A$8000,"BKK27",BookingRaw!$B$2:$B$8000,"="&Control!$B$1) | G6: =Control!$A$4 | H6: ="Booking on "&DAY(Control!$B$1)&" "&CHOOSE(MONTH(Control!$B$1),"JAN","FEB","MAR","APR","MAY","JUN","JUL","AUG","SEP","OCT","NOV","DEC") | I6: =SUMIFS(BookingRaw!$C$2:$C$8000,BookingRaw!$A$2:$A$8000,"LCH27",BookingRaw!$B$2:$B$8000,"="&Control!$B$1) | J6: =SUMIFS(BookingRaw!$D$2:$D$8000,BookingRaw!$A$2:$A$8000,"LCH27",BookingRaw!$B$2:$B$8000,"="&Control!$B$1)
A7: =Control!$A$4 | B7: ="Booking on "&IF(Control!$B$9=Control!$C$4,DAY(Control!$B$9)&" "&CHOOSE(MONTH(Control!$B$9),"JAN","FEB","MAR","APR","MAY","JUN","JUL","AUG","SEP","OCT","NOV","DEC"),IF(MONTH(Control!$B$9)=MONTH(Control!$C$4),DAY(Control!$B$9)&"-"&DAY(Control!$C$4)&" "&CHOOSE(MONTH(Control!$C$4),"JAN","FEB","MAR","APR","MAY","JUN","JUL","AUG","SEP","OCT","NOV","DEC"),DAY(Control!$B$9)&" "&CHOOSE(MONTH(Control!$B$9),"JAN","FEB","MAR","APR","MAY","JUN","JUL","AUG","SEP","OCT","NOV","DEC")&"-"&DAY(Control!$C$4)&" "&CHOOSE(MONTH(Control!$C$4),"JAN","FEB","MAR","APR","MAY","JUN","JUL","AUG","SEP","OCT","NOV","DEC"))) | C7: =SUMIFS(BookingRaw!$C$2:$C$8000,BookingRaw!$A$2:$A$8000,"BKK27",BookingRaw!$B$2:$B$8000,">="&Control!$B$9,BookingRaw!$B$2:$B$8000,"<="&Control!$C$4) | D7: =SUMIFS(BookingRaw!$D$2:$D$8000,BookingRaw!$A$2:$A$8000,"BKK27",BookingRaw!$B$2:$B$8000,">="&Control!$B$9,BookingRaw!$B$2:$B$8000,"<="&Control!$C$4) | G7: =Control!$A$4 | H7: ="Booking on "&IF(Control!$B$9=Control!$C$4,DAY(Control!$B$9)&" "&CHOOSE(MONTH(Control!$B$9),"JAN","FEB","MAR","APR","MAY","JUN","JUL","AUG","SEP","OCT","NOV","DEC"),IF(MONTH(Control!$B$9)=MONTH(Control!$C$4),DAY(Control!$B$9)&"-"&DAY(Control!$C$4)&" "&CHOOSE(MONTH(Control!$C$4),"JAN","FEB","MAR","APR","MAY","JUN","JUL","AUG","SEP","OCT","NOV","DEC"),DAY(Control!$B$9)&" "&CHOOSE(MONTH(Control!$B$9),"JAN","FEB","MAR","APR","MAY","JUN","JUL","AUG","SEP","OCT","NOV","DEC")&"-"&DAY(Control!$C$4)&" "&CHOOSE(MONTH(Control!$C$4),"JAN","FEB","MAR","APR","MAY","JUN","JUL","AUG","SEP","OCT","NOV","DEC"))) | I7: =SUMIFS(BookingRaw!$C$2:$C$8000,BookingRaw!$A$2:$A$8000,"LCH27",BookingRaw!$B$2:$B$8000,">="&Control!$B$9,BookingRaw!$B$2:$B$8000,"<="&Control!$C$4) | J7: =SUMIFS(BookingRaw!$D$2:$D$8000,BookingRaw!$A$2:$A$8000,"LCH27",BookingRaw!$B$2:$B$8000,">="&Control!$B$9,BookingRaw!$B$2:$B$8000,"<="&Control!$C$4) | M7: BOOKING | N7: 22RE | O7: 45RE
B8: ="AV Balance till "&DAY(Control!$C$4)&" "&CHOOSE(MONTH(Control!$C$4),"JAN","FEB","MAR","APR","MAY","JUN","JUL","AUG","SEP","OCT","NOV","DEC") | C8: =C4-C5-C6-C7 | D8: =D4-D5-D6-D7 | H8: ="AV Balance till "&DAY(Control!$C$4)&" "&CHOOSE(MONTH(Control!$C$4),"JAN","FEB","MAR","APR","MAY","JUN","JUL","AUG","SEP","OCT","NOV","DEC") | I8: =I4-I5-I6-I7 | J8: =J4-J5-J6-J7 | M8: BC | N8: =C5+C6+C7+C9+C11 | O8: =D5+D6+D7+D9+D11
A9: =Control!$A$5 | B9: ="Booking on "&IF(Control!$B5=Control!$C5,DAY(Control!$B5)&" "&CHOOSE(MONTH(Control!$B5),"JAN","FEB","MAR","APR","MAY","JUN","JUL","AUG","SEP","OCT","NOV","DEC"),IF(MONTH(Control!$B5)=MONTH(Control!$C5),DAY(Control!$B5)&"-"&DAY(Control!$C5)&" "&CHOOSE(MONTH(Control!$C5),"JAN","FEB","MAR","APR","MAY","JUN","JUL","AUG","SEP","OCT","NOV","DEC"),DAY(Control!$B5)&" "&CHOOSE(MONTH(Control!$B5),"JAN","FEB","MAR","APR","MAY","JUN","JUL","AUG","SEP","OCT","NOV","DEC")&"-"&DAY(Control!$C5)&" "&CHOOSE(MONTH(Control!$C5),"JAN","FEB","MAR","APR","MAY","JUN","JUL","AUG","SEP","OCT","NOV","DEC"))) | C9: =SUMIFS(BookingRaw!$C$2:$C$8000,BookingRaw!$A$2:$A$8000,"BKK27",BookingRaw!$B$2:$B$8000,">="&Control!$B5,BookingRaw!$B$2:$B$8000,"<="&Control!$C5) | D9: =SUMIFS(BookingRaw!$D$2:$D$8000,BookingRaw!$A$2:$A$8000,"BKK27",BookingRaw!$B$2:$B$8000,">="&Control!$B5,BookingRaw!$B$2:$B$8000,"<="&Control!$C5) | G9: =Control!$A$5 | H9: ="Booking on "&IF(Control!$B5=Control!$C5,DAY(Control!$B5)&" "&CHOOSE(MONTH(Control!$B5),"JAN","FEB","MAR","APR","MAY","JUN","JUL","AUG","SEP","OCT","NOV","DEC"),IF(MONTH(Control!$B5)=MONTH(Control!$C5),DAY(Control!$B5)&"-"&DAY(Control!$C5)&" "&CHOOSE(MONTH(Control!$C5),"JAN","FEB","MAR","APR","MAY","JUN","JUL","AUG","SEP","OCT","NOV","DEC"),DAY(Control!$B5)&" "&CHOOSE(MONTH(Control!$B5),"JAN","FEB","MAR","APR","MAY","JUN","JUL","AUG","SEP","OCT","NOV","DEC")&"-"&DAY(Control!$C5)&" "&CHOOSE(MONTH(Control!$C5),"JAN","FEB","MAR","APR","MAY","JUN","JUL","AUG","SEP","OCT","NOV","DEC"))) | I9: =SUMIFS(BookingRaw!$C$2:$C$8000,BookingRaw!$A$2:$A$8000,"LCH27",BookingRaw!$B$2:$B$8000,">="&Control!$B5,BookingRaw!$B$2:$B$8000,"<="&Control!$C5) | J9: =SUMIFS(BookingRaw!$D$2:$D$8000,BookingRaw!$A$2:$A$8000,"LCH27",BookingRaw!$B$2:$B$8000,">="&Control!$B5,BookingRaw!$B$2:$B$8000,"<="&Control!$C5) | M9: HAST | N9: =I5+I6+I7+I9+I11 | O9: =J5+J6+J7+J9+J11
B10: ="AV Balance till "&DAY(Control!$C5)&" "&CHOOSE(MONTH(Control!$C5),"JAN","FEB","MAR","APR","MAY","JUN","JUL","AUG","SEP","OCT","NOV","DEC") | C10: =C8-C9 | D10: =D8-D9 | H10: ="AV Balance till "&DAY(Control!$C5)&" "&CHOOSE(MONTH(Control!$C5),"JAN","FEB","MAR","APR","MAY","JUN","JUL","AUG","SEP","OCT","NOV","DEC") | I10: =I8-I9 | J10: =J8-J9 | M10: TOTAL | N10: =SUM(N8:N9) | O10: =SUM(O8:O9)
A11: =Control!$A$6 | B11: ="Booking on "&IF(Control!$B6=Control!$C6,DAY(Control!$B6)&" "&CHOOSE(MONTH(Control!$B6),"JAN","FEB","MAR","APR","MAY","JUN","JUL","AUG","SEP","OCT","NOV","DEC"),IF(MONTH(Control!$B6)=MONTH(Control!$C6),DAY(Control!$B6)&"-"&DAY(Control!$C6)&" "&CHOOSE(MONTH(Control!$C6),"JAN","FEB","MAR","APR","MAY","JUN","JUL","AUG","SEP","OCT","NOV","DEC"),DAY(Control!$B6)&" "&CHOOSE(MONTH(Control!$B6),"JAN","FEB","MAR","APR","MAY","JUN","JUL","AUG","SEP","OCT","NOV","DEC")&"-"&DAY(Control!$C6)&" "&CHOOSE(MONTH(Control!$C6),"JAN","FEB","MAR","APR","MAY","JUN","JUL","AUG","SEP","OCT","NOV","DEC"))) | C11: =SUMIFS(BookingRaw!$C$2:$C$8000,BookingRaw!$A$2:$A$8000,"BKK27",BookingRaw!$B$2:$B$8000,">="&Control!$B6,BookingRaw!$B$2:$B$8000,"<="&DATE(2026,10,10)) | D11: =SUMIFS(BookingRaw!$D$2:$D$8000,BookingRaw!$A$2:$A$8000,"BKK27",BookingRaw!$B$2:$B$8000,">="&Control!$B6,BookingRaw!$B$2:$B$8000,"<="&DATE(2026,10,10)) | G11: =Control!$A$6 | H11: ="Booking on "&IF(Control!$B6=Control!$C6,DAY(Control!$B6)&" "&CHOOSE(MONTH(Control!$B6),"JAN","FEB","MAR","APR","MAY","JUN","JUL","AUG","SEP","OCT","NOV","DEC"),IF(MONTH(Control!$B6)=MONTH(Control!$C6),DAY(Control!$B6)&"-"&DAY(Control!$C6)&" "&CHOOSE(MONTH(Control!$C6),"JAN","FEB","MAR","APR","MAY","JUN","JUL","AUG","SEP","OCT","NOV","DEC"),DAY(Control!$B6)&" "&CHOOSE(MONTH(Control!$B6),"JAN","FEB","MAR","APR","MAY","JUN","JUL","AUG","SEP","OCT","NOV","DEC")&"-"&DAY(Control!$C6)&" "&CHOOSE(MONTH(Control!$C6),"JAN","FEB","MAR","APR","MAY","JUN","JUL","AUG","SEP","OCT","NOV","DEC"))) | I11: =SUMIFS(BookingRaw!$C$2:$C$8000,BookingRaw!$A$2:$A$8000,"LCH27",BookingRaw!$B$2:$B$8000,">="&Control!$B6,BookingRaw!$B$2:$B$8000,"<="&DATE(2026,10,10)) | J11: =SUMIFS(BookingRaw!$D$2:$D$8000,BookingRaw!$A$2:$A$8000,"LCH27",BookingRaw!$B$2:$B$8000,">="&Control!$B6,BookingRaw!$B$2:$B$8000,"<="&DATE(2026,10,10))
B12: ="AV Balance till "&DAY(Control!$C6)&" "&CHOOSE(MONTH(Control!$C6),"JAN","FEB","MAR","APR","MAY","JUN","JUL","AUG","SEP","OCT","NOV","DEC") | C12: =C10-C11 | D12: =D10-D11 | H12: ="AV Balance till "&DAY(Control!$C6)&" "&CHOOSE(MONTH(Control!$C6),"JAN","FEB","MAR","APR","MAY","JUN","JUL","AUG","SEP","OCT","NOV","DEC") | I12: =I10-I11 | J12: =J10-J11 | M12: BALANCE | N12: 22RE | O12: 45RE
M13: BC | N13: =C12 | O13: =D12
A14: Remarks: | B14: AV = stock with move code IED / IEP / IER (available) | DMG = move code OER (damaged) | M14: HAST | N14: =I12 | O14: =J12
C15: 20'RE | D15: 40'RH | I15: 20'RE | J15: 40'RH | M15: TOTAL | N15: =SUM(N13:N14) | O15: =SUM(O13:O14)
B16: AV | C16: =COUNTIFS(StockRaw!$A$2:$A$108,"BKK27",StockRaw!$B$2:$B$108,"22RE",StockRaw!$C$2:$C$108,"IED")+COUNTIFS(StockRaw!$A$2:$A$108,"BKK27",StockRaw!$B$2:$B$108,"22RE",StockRaw!$C$2:$C$108,"IEP")+COUNTIFS(StockRaw!$A$2:$A$108,"BKK27",StockRaw!$B$2:$B$108,"22RE",StockRaw!$C$2:$C$108,"IER") | D16: =COUNTIFS(StockRaw!$A$2:$A$108,"BKK27",StockRaw!$B$2:$B$108,"45RE",StockRaw!$C$2:$C$108,"IED")+COUNTIFS(StockRaw!$A$2:$A$108,"BKK27",StockRaw!$B$2:$B$108,"45RE",StockRaw!$C$2:$C$108,"IEP")+COUNTIFS(StockRaw!$A$2:$A$108,"BKK27",StockRaw!$B$2:$B$108,"45RE",StockRaw!$C$2:$C$108,"IER") | H16: AV | I16: =COUNTIFS(StockRaw!$A$2:$A$108,"LCH27",StockRaw!$B$2:$B$108,"22RE",StockRaw!$C$2:$C$108,"IED")+COUNTIFS(StockRaw!$A$2:$A$108,"LCH27",StockRaw!$B$2:$B$108,"22RE",StockRaw!$C$2:$C$108,"IEP")+COUNTIFS(StockRaw!$A$2:$A$108,"LCH27",StockRaw!$B$2:$B$108,"22RE",StockRaw!$C$2:$C$108,"IER") | J16: =COUNTIFS(StockRaw!$A$2:$A$108,"LCH27",StockRaw!$B$2:$B$108,"45RE",StockRaw!$C$2:$C$108,"IED")+COUNTIFS(StockRaw!$A$2:$A$108,"LCH27",StockRaw!$B$2:$B$108,"45RE",StockRaw!$C$2:$C$108,"IEP")+COUNTIFS(StockRaw!$A$2:$A$108,"LCH27",StockRaw!$B$2:$B$108,"45RE",StockRaw!$C$2:$C$108,"IER")
B17: DMG | C17: =COUNTIFS(StockRaw!$A$2:$A$108,"BKK27",StockRaw!$B$2:$B$108,"22RE",StockRaw!$C$2:$C$108,"OER") | D17: =COUNTIFS(StockRaw!$A$2:$A$108,"BKK27",StockRaw!$B$2:$B$108,"45RE",StockRaw!$C$2:$C$108,"OER") | H17: DMG | I17: =COUNTIFS(StockRaw!$A$2:$A$108,"LCH27",StockRaw!$B$2:$B$108,"22RE",StockRaw!$C$2:$C$108,"OER") | J17: =COUNTIFS(StockRaw!$A$2:$A$108,"LCH27",StockRaw!$B$2:$B$108,"45RE",StockRaw!$C$2:$C$108,"OER")
B20: BKK / BC2 (BKK27) | H20: LCH / HAST (LCH27)
B21: YEAR BUILT 5 YEARS FOR DURIAN SEASON | C21: CARRIER | D21: DAIKIN | E21: THERMO KING | H21: YEAR BUILT 5 YEARS FOR DURIAN SEASON | I21: CARRIER | J21: DAIKIN | K21: THERMO KING
C22: 45RE | D22: 45RE | E22: 45RE | I22: 45RE | J22: 45RE | K22: 45RE
B23: 2026 | C23: 0 | D23: 0 | E23: 0 | H23: 2026 | I23: 0 | J23: 0 | K23: 0
B24: 2025 | C24: 5 | D24: 0 | E24: 0 | H24: 2025 | I24: 8 | J24: 0 | K24: 0
B25: 2024 | C25: 0 | D25: 0 | E25: 0 | H25: 2024 | I25: 0 | J25: 0 | K25: 0
B26: 2023 | C26: 1 | D26: 0 | E26: 0 | H26: 2023 | I26: 3 | J26: 0 | K26: 0
B27: 2022 | C27: 0 | D27: 0 | E27: 0 | H27: 2022 | I27: 0 | J27: 0 | K27: 0
B28: 2021 | C28: 7 | D28: 0 | E28: 0 | H28: 2021 | I28: 7 | J28: 0 | K28: 0
B29: TOTAL | C29: 13 | D29: 0 | E29: 0 | H29: TOTAL | I29: 18 | J29: 0 | K29: 0
D30: OVER 5 Y | E30: 20 | J30: OVER 5 Y | K30: 20
B33: BKK27 / BC2 — Stock by Built Year x Brand x Size | J33: LCH27 / HAST — Stock by Built Year x Brand x Size
B34: YEAR BUILT | C34: CARRIER | E34: DAIKIN | G34: THERMO KING | J34: YEAR BUILT | K34: CARRIER | M34: DAIKIN | O34: THERMO KING
C35: 20'RE | D35: 40'RH | E35: 20'RE | F35: 40'RH | G35: 20'RE | H35: 40'RH | K35: 20'RE | L35: 40'RH | M35: 20'RE | N35: 40'RH | O35: 20'RE | P35: 40'RH
B36: 2026 | J36: 2026
B37: 2025 | D37: 5 | E37: 3 | J37: 2025 | L37: 8
B38: 2024 | J38: 2024
B39: 2023 | D39: 1 | J39: 2023 | L39: 3
B40: 2022 | J40: 2022
B41: 2021 | C41: 8 | D41: 7 | J41: 2021 | K41: 1 | L41: 7
B42: 2020 | C42: 1 | D42: 8 | J42: 2020 | L42: 4
B43: 2019 | C43: 4 | D43: 4 | J43: 2019 | L43: 8
B44: 2018 | C44: 1 | J44: 2018 | L44: 1
...

Sheet Dashboard
B1: ='TOTAL RH'!A1
B4: SHORTFALL ALERT | F4: COMBINED 40'RH STOCK | J4: COMBINED 40'RH BOOKING | N4: COMBINED 40'RH BALANCE
B5: =MIN('TOTAL RH'!D12,'TOTAL RH'!J12) | F5: ='TOTAL RH'!O5 | J5: ='TOTAL RH'!O10 | N5: ='TOTAL RH'!O15
B6: ="BKK27/LCH27 40'RH, worse "&'TOTAL RH'!B12 | F6: BKK27 + LCH27 | J6: pending + all weeks | N6: ="pending + all weeks, both depots, "&'TOTAL RH'!B12
B8: DETAIL BY DEPOT
B9: ='TOTAL RH'!B2 | H9: ='TOTAL RH'!H2
C10: 20'RE | D10: 40'RH | I10: 20'RE | J10: 40'RH
B11: ='TOTAL RH'!B4 | C11: ='TOTAL RH'!C4 | D11: ='TOTAL RH'!D4 | H11: ='TOTAL RH'!H4 | I11: ='TOTAL RH'!I4 | J11: ='TOTAL RH'!J4
B12: ='TOTAL RH'!B5 | C12: ='TOTAL RH'!C5 | D12: ='TOTAL RH'!D5 | H12: ='TOTAL RH'!H5 | I12: ='TOTAL RH'!I5 | J12: ='TOTAL RH'!J5
B13: ='TOTAL RH'!B6 | C13: ='TOTAL RH'!C6 | D13: ='TOTAL RH'!D6 | H13: ='TOTAL RH'!H6 | I13: ='TOTAL RH'!I6 | J13: ='TOTAL RH'!J6
B14: ='TOTAL RH'!B7 | C14: ='TOTAL RH'!C7 | D14: ='TOTAL RH'!D7 | H14: ='TOTAL RH'!H7 | I14: ='TOTAL RH'!I7 | J14: ='TOTAL RH'!J7
B15: ='TOTAL RH'!B8 | C15: ='TOTAL RH'!C8 | D15: ='TOTAL RH'!D8 | H15: ='TOTAL RH'!H8 | I15: ='TOTAL RH'!I8 | J15: ='TOTAL RH'!J8
B16: ='TOTAL RH'!B9 | C16: ='TOTAL RH'!C9 | D16: ='TOTAL RH'!D9 | H16: ='TOTAL RH'!H9 | I16: ='TOTAL RH'!I9 | J16: ='TOTAL RH'!J9
B17: ='TOTAL RH'!B10 | C17: ='TOTAL RH'!C10 | D17: ='TOTAL RH'!D10 | H17: ='TOTAL RH'!H10 | I17: ='TOTAL RH'!I10 | J17: ='TOTAL RH'!J10
B18: ='TOTAL RH'!B11 | C18: ='TOTAL RH'!C11 | D18: ='TOTAL RH'!D11 | H18: ='TOTAL RH'!H11 | I18: ='TOTAL RH'!I11 | J18: ='TOTAL RH'!J11
B19: ='TOTAL RH'!B12 | C19: ='TOTAL RH'!C12 | D19: ='TOTAL RH'!D12 | H19: ='TOTAL RH'!H12 | I19: ='TOTAL RH'!I12 | J19: ='TOTAL RH'!J12
B22: REMARKS (AV = move code IED/IEP/IER, DMG = move code OER)
B23: ='TOTAL RH'!B2 | H23: ='TOTAL RH'!H2
C24: 20'RE | D24: 40'RH | I24: 20'RE | J24: 40'RH
B25: AV | C25: ='TOTAL RH'!C16 | D25: ='TOTAL RH'!D16 | H25: AV | I25: ='TOTAL RH'!I16 | J25: ='TOTAL RH'!J16
B26: DMG | C26: ='TOTAL RH'!C17 | D26: ='TOTAL RH'!D17 | H26: DMG | I26: ='TOTAL RH'!I17 | J26: ='TOTAL RH'!J17
B29: RF SEASONAL — build year
B30: BKK27 2020-26 BUILT | F30: LCH27 2020-26 BUILT | J30: PEAK BUILD YEAR
B31: =SUM('TOTAL RH'!D36:D42)+SUM('TOTAL RH'!F36:F42)+SUM('TOTAL RH'!H36:H42) | F31: =SUM('TOTAL RH'!L36:L42)+SUM('TOTAL RH'!N36:N42)+SUM('TOTAL RH'!P36:P42) | J31: ="2021"
B32: of 40'RH on hand | F32: of 40'RH on hand | J32: 14 units across both depots
B34: BKK27 DURIAN (2021-2026) | F34: BKK27 NON DURIAN (≤ 2020) | J34: LCH27 DURIAN (2021-2026) | N34: LCH27 NON DURIAN (≤ 2020)
B35: ='TOTAL RH'!B58 | F35: ='TOTAL RH'!F58 | J35: ='TOTAL RH'!J58 | N35: ='TOTAL RH'!N58
B36: 40'RH stock | F36: 40'RH stock | J36: 40'RH stock | N36: 40'RH stock
B38: BKK27 current mix | H38: LCH27 current mix
C39: 22RE | D39: 45RE | I39: 22RE | J39: 45RE
B40: CARRIER | C40: ='TOTAL RH'!C53 | D40: ='TOTAL RH'!D53 | H40: CARRIER | I40: ='TOTAL RH'!K53 | J40: ='TOTAL RH'!L53
B41: DAIKIN | C41: ='TOTAL RH'!E53 | D41: ='TOTAL RH'!F53 | H41: DAIKIN | I41: ='TOTAL RH'!M53 | J41: ='TOTAL RH'!N53
B42: THERMO KING | C42: ='TOTAL RH'!G53 | D42: ='TOTAL RH'!H53 | H42: THERMO KING | I42: ='TOTAL RH'!O53 | J42: ='TOTAL RH'!P53
B44: Full 2010-2026 Year x Brand x Size breakdown is on the TOTAL RH sheet.
