Workbook

Sheet Control
A1: Report date | B1: =TODAY() -> 46275
A3: WK# | B3: Monday | C3: Saturday | D3: ISO week
A4: =_xlfn.ISOWEEKNUM($B$4) -> 37 | B4: =$B$1-(WEEKDAY($B$1,2)-1) -> 46272 | C4: =$B$4+5 -> 46277 | D4: =_xlfn.ISOWEEKNUM($B$4) -> 37
A5: =_xlfn.ISOWEEKNUM($B$5) -> 38 | B5: =$B$4+7 -> 46279 | C5: =$B$5+5 -> 46284 | D5: =_xlfn.ISOWEEKNUM($B$5) -> 38
A6: =_xlfn.ISOWEEKNUM($B$6) -> 39 | B6: =$B$5+7 -> 46286 | C6: =$B$6+5 -> 46291 | D6: =_xlfn.ISOWEEKNUM($B$6) -> 39
A7: =_xlfn.ISOWEEKNUM($B$7) -> 40 | B7: =$B$6+7 -> 46293 | C7: =$B$7+5 -> 46298 | D7: =_xlfn.ISOWEEKNUM($B$7) -> 40
A9: Rest of WK1 start | B9: =$B$1+1 -> 46276

Sheet BookingRaw
A1: Location | B1: Date | C1: 20'GP | D1: 40'GP | E1: 40'HC | F1: 20'RE | G1: 40'RH | H1: 20'OT | I1: 40'OT | J1: 20'FR | K1: 40'FR
A2: LCH27 | B2: 46275 | C2: 0 | D2: 0 | E2: 0 | F2: 1 | G2: 0 | H2: 0 | I2: 0 | J2: 0 | K2: 0
A3: BKK27 | B3: 46279 | C3: 0 | D3: 0 | E3: 0 | F3: 1 | G3: 0 | H3: 0 | I3: 0 | J3: 0 | K3: 0
A4: BKK27 | B4: 46279 | C4: 0 | D4: 0 | E4: 0 | F4: 1 | G4: 0 | H4: 0 | I4: 0 | J4: 0 | K4: 0
A5: BKK27 | B5: 46279 | C5: 0 | D5: 0 | E5: 0 | F5: 1 | G5: 0 | H5: 0 | I5: 0 | J5: 0 | K5: 0
A6: BKK27 | B6: 46279 | C6: 0 | D6: 0 | E6: 0 | F6: 1 | G6: 0 | H6: 0 | I6: 0 | J6: 0 | K6: 0
A7: BKK27 | B7: 46280 | C7: 0 | D7: 0 | E7: 0 | F7: 1 | G7: 0 | H7: 0 | I7: 0 | J7: 0 | K7: 0
A8: BKK27 | B8: 46280 | C8: 0 | D8: 0 | E8: 0 | F8: 1 | G8: 0 | H8: 0 | I8: 0 | J8: 0 | K8: 0
A9: BKK27 | B9: 46281 | C9: 0 | D9: 0 | E9: 0 | F9: 1 | G9: 0 | H9: 0 | I9: 0 | J9: 0 | K9: 0
A10: BKK27 | B10: 46281 | C10: 0 | D10: 0 | E10: 0 | F10: 1 | G10: 0 | H10: 0 | I10: 0 | J10: 0 | K10: 0
A11: BKK27 | B11: 46283 | C11: 0 | D11: 0 | E11: 0 | F11: 1 | G11: 0 | H11: 0 | I11: 0 | J11: 0 | K11: 0
A12: BKK27 | B12: 46283 | C12: 0 | D12: 0 | E12: 0 | F12: 1 | G12: 0 | H12: 0 | I12: 0 | J12: 0 | K12: 0
A13: BKK27 | B13: 46283 | C13: 0 | D13: 0 | E13: 0 | F13: 1 | G13: 0 | H13: 0 | I13: 0 | J13: 0 | K13: 0
... A103: BKK27 | B103: 46279 | C103: 0 | D103: 0 | E103: 0 | F103: 0 | G103: 6 | H103: 0 | I103: 0 | J103: 0 | K103: 0

Sheet Summary
A1: ="Stock Daily - Reefer (Stock vs Booking) as of "&DAY(Control!$B$1)&" "&CHOOSE(MONTH(Control!$B$1),"Jan","Feb","Mar","Apr","May","Jun","Jul","Aug","Sep","Oct","Nov","Dec")&" "&YEAR(Control!$B$1) -> Stock Daily - Reefer (Stock vs Booking) as of 10 Sep 2026
A2: ="Report date "&TEXT(Control!$B$1,"yyyy-mm-dd")&" Legend: RE = reefer (blue) OT/FR = special (brown) AV Balance = stock - cumulative booking (yellow; red = short)" -> Report date 2026-09-10 Legend: RE = reefer (blue) OT/FR = special (brown) AV Balance = stock - cumulative booking (yellow; red = short)
A3: BKK | M3: BKK | Y3: LCH
A4: BKK25 | M4: BKK01+BKK04 | Y4: LCH27
A5: WK | C5: 20'GP | D5: 40'GP | E5: 40'HC | F5: 20'RE | G5: 40'RH | H5: 20'OT | I5: 40'OT | J5: 20'FR | K5: 40'FR | M5: WK | O5: 20'GP | P5: 40'GP | Q5: 40'HC | R5: 20'RE | S5: 40'RH | T5: 20'OT | U5: 40'OT | V5: 20'FR | W5: 40'FR | Y5: WK | AA5: 20'GP | AB5: 40'GP | AC5: 40'HC | AD5: 20'RE | AE5: 40'RH | AF5: 20'OT | AG5: 40'OT | AH5: 20'FR | AI5: 40'FR
B6: Stock empty in yard | C6: 0 | D6: 0 | E6: 0 | F6: 0 | G6: 0 | H6: 0 | I6: 0 | J6: 0 | K6: 0 | N6: Stock empty in yard | O6: 0 | P6: 0 | Q6: 0 | R6: 0 | S6: 0 | T6: 0 | U6: 0 | V6: 0 | W6: 0 | Z6: Stock empty in yard | AA6: 0 | AB6: 0 | AC6: 0 | AD6: 7 | AE6: 66 | AF6: 0 | AG6: 0 | AH6: 0 | AI6: 0
A7: =Control!$A$4 -> 37 | B7: Booking Pending pick up | C7: =SUMIFS(BookingRaw!$C$2:$C$600,BookingRaw!$A$2:$A$600,"BKK25",BookingRaw!$B$2:$B$600,"<"&Control!$B$1) -> 0 | D7: =SUMIFS(BookingRaw!$D$2:$D$600,BookingRaw!$A$2:$A$600,"BKK25",BookingRaw!$B$2:$B$600,"<"&Control!$B$1) -> 0 | E7: =SUMIFS(BookingRaw!$E$2:$E$600,BookingRaw!$A$2:$A$600,"BKK25",BookingRaw!$B$2:$B$600,"<"&Control!$B$1) -> 0 | F7: =SUMIFS(BookingRaw!$F$2:$F$600,BookingRaw!$A$2:$A$600,"BKK25",BookingRaw!$B$2:$B$600,"<"&Control!$B$1) -> 0 | G7: =SUMIFS(BookingRaw!$G$2:$G$600,BookingRaw!$A$2:$A$600,"BKK25",BookingRaw!$B$2:$B$600,"<"&Control!$B$1) -> 0 | H7: =SUMIFS(BookingRaw!$H$2:$H$600,BookingRaw!$A$2:$A$600,"BKK25",BookingRaw!$B$2:$B$600,"<"&Control!$B$1) -> 0 | I7: =SUMIFS(BookingRaw!$I$2:$I$600,BookingRaw!$A$2:$A$600,"BKK25",BookingRaw!$B$2:$B$600,"<"&Control!$B$1) -> 0 | J7: =SUMIFS(BookingRaw!$J$2:$J$600,BookingRaw!$A$2:$A$600,"BKK25",BookingRaw!$B$2:$B$600,"<"&Control!$B$1) -> 0 | K7: =SUMIFS(BookingRaw!$K$2:$K$600,BookingRaw!$A$2:$A$600,"BKK25",BookingRaw!$B$2:$B$600,"<"&Control!$B$1) -> 0 | M7: =Control!$A$4 -> 37 | N7: Booking Pending pick up | O7: =SUMIFS(BookingRaw!$C$2:$C$600,BookingRaw!$A$2:$A$600,"BKK01",BookingRaw!$B$2:$B$600,"<"&Control!$B$1) -> 0 | P7: =SUMIFS(BookingRaw!$D$2:$D$600,BookingRaw!$A$2:$A$600,"BKK01",BookingRaw!$B$2:$B$600,"<"&Control!$B$1) -> 0 | Q7: =SUMIFS(BookingRaw!$E$2:$E$600,BookingRaw!$A$2:$A$600,"BKK01",BookingRaw!$B$2:$B$600,"<"&Control!$B$1) -> 0 | R7: =SUMIFS(BookingRaw!$F$2:$F$600,BookingRaw!$A$2:$A$600,"BKK01",BookingRaw!$B$2:$B$600,"<"&Control!$B$1) -> 0 | S7: =SUMIFS(BookingRaw!$G$2:$G$600,BookingRaw!$A$2:$A$600,"BKK01",BookingRaw!$B$2:$B$600,"<"&Control!$B$1) -> 0 | T7: =SUMIFS(BookingRaw!$H$2:$H$600,BookingRaw!$A$2:$A$600,"BKK01",BookingRaw!$B$2:$B$600,"<"&Control!$B$1) -> 0 | U7: =SUMIFS(BookingRaw!$I$2:$I$600,BookingRaw!$A$2:$A$600,"BKK01",BookingRaw!$B$2:$B$600,"<"&Control!$B$1) -> 0 | V7: =SUMIFS(BookingRaw!$J$2:$J$600,BookingRaw!$A$2:$A$600,"BKK01",BookingRaw!$B$2:$B$600,"<"&Control!$B$1) -> 0 | W7: =SUMIFS(BookingRaw!$K$2:$K$600,BookingRaw!$A$2:$A$600,"BKK01",BookingRaw!$B$2:$B$600,"<"&Control!$B$1) -> 0 | Y7: =Control!$A$4 -> 37 | Z7: Booking Pending pick up | AA7: =SUMIFS(BookingRaw!$C$2:$C$600,BookingRaw!$A$2:$A$600,"LCH27",BookingRaw!$B$2:$B$600,"<"&Control!$B$1) -> 0 | AB7: =SUMIFS(BookingRaw!$D$2:$D$600,BookingRaw!$A$2:$A$600,"LCH27",BookingRaw!$B$2:$B$600,"<"&Control!$B$1) -> 0 | AC7: =SUMIFS(BookingRaw!$E$2:$E$600,BookingRaw!$A$2:$A$600,"LCH27",BookingRaw!$B$2:$B$600,"<"&Control!$B$1) -> 0 | AD7: =SUMIFS(BookingRaw!$F$2:$F$600,BookingRaw!$A$2:$A$600,"LCH27",BookingRaw!$B$2:$B$600,"<"&Control!$B$1) -> 0 | AE7: =SUMIFS(BookingRaw!$G$2:$G$600,BookingRaw!$A$2:$A$600,"LCH27",BookingRaw!$B$2:$B$600,"<"&Control!$B$1) -> 7 | AF7: =SUMIFS(BookingRaw!$H$2:$H$600,BookingRaw!$A$2:$A$600,"LCH27",BookingRaw!$B$2:$B$600,"<"&Control!$B$1) -> 0 | AG7: =SUMIFS(BookingRaw!$I$2:$I$600,BookingRaw!$A$2:$A$600,"LCH27",BookingRaw!$B$2:$B$600,"<"&Control!$B$1) -> 0 | AH7: =SUMIFS(BookingRaw!$J$2:$J$600,BookingRaw!$A$2:$A$600,"LCH27",BookingRaw!$B$2:$B$600,"<"&Control!$B$1) -> 0 | AI7: =SUMIFS(BookingRaw!$K$2:$K$600,BookingRaw!$A$2:$A$600,"LCH27",BookingRaw!$B$2:$B$600,"<"&Control!$B$1) -> 0
A8: =Control!$A$4 -> 37 | B8: ="Booking on "&DAY(Control!$B$1)&" "&CHOOSE(MONTH(Control!$B$1),"Jan","Feb","Mar","Apr","May","Jun","Jul","Aug","Sep","Oct","Nov","Dec") -> Booking on 10 Sep | C8: =SUMIFS(BookingRaw!$C$2:$C$600,BookingRaw!$A$2:$A$600,"BKK25",BookingRaw!$B$2:$B$600,"="&Control!$B$1) -> 0 | D8: =SUMIFS(BookingRaw!$D$2:$D$600,BookingRaw!$A$2:$A$600,"BKK25",BookingRaw!$B$2:$B$600,"="&Control!$B$1) -> 0 | E8: =SUMIFS(BookingRaw!$E$2:$E$600,BookingRaw!$A$2:$A$600,"BKK25",BookingRaw!$B$2:$B$600,"="&Control!$B$1) -> 0 | F8: =SUMIFS(BookingRaw!$F$2:$F$600,BookingRaw!$A$2:$A$600,"BKK25",BookingRaw!$B$2:$B$600,"="&Control!$B$1) -> 0 | G8: =SUMIFS(BookingRaw!$G$2:$G$600,BookingRaw!$A$2:$A$600,"BKK25",BookingRaw!$B$2:$B$600,"="&Control!$B$1) -> 0 | H8: =SUMIFS(BookingRaw!$H$2:$H$600,BookingRaw!$A$2:$A$600,"BKK25",BookingRaw!$B$2:$B$600,"="&Control!$B$1) -> 0 | I8: =SUMIFS(BookingRaw!$I$2:$I$600,BookingRaw!$A$2:$A$600,"BKK25",BookingRaw!$B$2:$B$600,"="&Control!$B$1) -> 0 | J8: =SUMIFS(BookingRaw!$J$2:$J$600,BookingRaw!$A$2:$A$600,"BKK25",BookingRaw!$B$2:$B$600,"="&Control!$B$1) -> 0 | K8: =SUMIFS(BookingRaw!$K$2:$K$600,BookingRaw!$A$2:$A$600,"BKK25",BookingRaw!$B$2:$B$600,"="&Control!$B$1) -> 0 | M8: =Control!$A$4 -> 37 | N8: ="Booking on "&DAY(Control!$B$1)&" "&CHOOSE(MONTH(Control!$B$1),"Jan","Feb","Mar","Apr","May","Jun","Jul","Aug","Sep","Oct","Nov","Dec") -> Booking on 10 Sep | O8: =SUMIFS(BookingRaw!$C$2:$C$600,BookingRaw!$A$2:$A$600,"BKK01",BookingRaw!$B$2:$B$600,"="&Control!$B$1) -> 0 | P8: =SUMIFS(BookingRaw!$D$2:$D$600,BookingRaw!$A$2:$A$600,"BKK01",BookingRaw!$B$2:$B$600,"="&Control!$B$1) -> 0 | Q8: =SUMIFS(BookingRaw!$E$2:$E$600,BookingRaw!$A$2:$A$600,"BKK01",BookingRaw!$B$2:$B$600,"="&Control!$B$1) -> 0 | R8: =SUMIFS(BookingRaw!$F$2:$F$600,BookingRaw!$A$2:$A$600,"BKK01",BookingRaw!$B$2:$B$600,"="&Control!$B$1) -> 0 | S8: =SUMIFS(BookingRaw!$G$2:$G$600,BookingRaw!$A$2:$A$600,"BKK01",BookingRaw!$B$2:$B$600,"="&Control!$B$1) -> 0 | T8: =SUMIFS(BookingRaw!$H$2:$H$600,BookingRaw!$A$2:$A$600,"BKK01",BookingRaw!$B$2:$B$600,"="&Control!$B$1) -> 0 | U8: =SUMIFS(BookingRaw!$I$2:$I$600,BookingRaw!$A$2:$A$600,"BKK01",BookingRaw!$B$2:$B$600,"="&Control!$B$1) -> 0 | V8: =SUMIFS(BookingRaw!$J$2:$J$600,BookingRaw!$A$2:$A$600,"BKK01",BookingRaw!$B$2:$B$600,"="&Control!$B$1) -> 0 | W8: =SUMIFS(BookingRaw!$K$2:$K$600,BookingRaw!$A$2:$A$600,"BKK01",BookingRaw!$B$2:$B$600,"="&Control!$B$1) -> 0 | Y8: =Control!$A$4 -> 37 | Z8: ="Booking on "&DAY(Control!$B$1)&" "&CHOOSE(MONTH(Control!$B$1),"Jan","Feb","Mar","Apr","May","Jun","Jul","Aug","Sep","Oct","Nov","Dec") -> Booking on 10 Sep | AA8: =SUMIFS(BookingRaw!$C$2:$C$600,BookingRaw!$A$2:$A$600,"LCH27",BookingRaw!$B$2:$B$600,"="&Control!$B$1) -> 0 | AB8: =SUMIFS(BookingRaw!$D$2:$D$600,BookingRaw!$A$2:$A$600,"LCH27",BookingRaw!$B$2:$B$600,"="&Control!$B$1) -> 0 | AC8: =SUMIFS(BookingRaw!$E$2:$E$600,BookingRaw!$A$2:$A$600,"LCH27",BookingRaw!$B$2:$B$600,"="&Control!$B$1) -> 0 | AD8: =SUMIFS(BookingRaw!$F$2:$F$600,BookingRaw!$A$2:$A$600,"LCH27",BookingRaw!$B$2:$B$600,"="&Control!$B$1) -> 1 | AE8: =SUMIFS(BookingRaw!$G$2:$G$600,BookingRaw!$A$2:$A$600,"LCH27",BookingRaw!$B$2:$B$600,"="&Control!$B$1) -> 2 | AF8: =SUMIFS(BookingRaw!$H$2:$H$600,BookingRaw!$A$2:$A$600,"LCH27",BookingRaw!$B$2:$B$600,"="&Control!$B$1) -> 0 | AG8: =SUMIFS(BookingRaw!$I$2:$I$600,BookingRaw!$A$2:$A$600,"LCH27",BookingRaw!$B$2:$B$600,"="&Control!$B$1) -> 0 | AH8: =SUMIFS(BookingRaw!$J$2:$J$600,BookingRaw!$A$2:$A$600,"LCH27",BookingRaw!$B$2:$B$600,"="&Control!$B$1) -> 0 | AI8: =SUMIFS(BookingRaw!$K$2:$K$600,BookingRaw!$A$2:$A$600,"LCH27",BookingRaw!$B$2:$B$600,"="&Control!$B$1) -> 0
A9: =Control!$A$4 -> 37 | B9: =IF(Control!$B$9=Control!$C$4,DAY(Control!$B$9)&" "&CHOOSE(MONTH(Control!$B$9),"Jan","Feb","Mar","Apr","May","Jun","Jul","Aug","Sep","Oct","Nov","Dec"),"Booking on "&IF(MONTH(Control!$B$9)=MONTH(Control!$C$4),DAY(Control!$B$9)&"-"&DAY(Control!$C$4)&" "&CHOOSE(MONTH(Control!$C$4),"Jan","Feb","Mar","Apr","May","Jun","Jul","Aug","Sep","Oct","Nov","Dec"),DAY(Control!$B$9)&" "&CHOOSE(MONTH(Control!$B$9),"Jan","Feb","Mar","Apr","May","Jun","Jul","Aug","Sep","Oct","Nov","Dec")&"-"&DAY(Control!$C$4)&" "&CHOOSE(MONTH(Control!$C$4),"Jan","Feb","Mar","Apr","May","Jun","Jul","Aug","Sep","Oct","Nov","Dec"))) -> Booking on 11-12 Sep | C9: =SUMIFS(BookingRaw!$C$2:$C$600,BookingRaw!$A$2:$A$600,"BKK25",BookingRaw!$B$2:$B$600,">="&Control!$B$9,BookingRaw!$B$2:$B$600,"<="&Control!$C$4) -> 0 | D9: =SUMIFS(BookingRaw!$D$2:$D$600,BookingRaw!$A$2:$A$600,"BKK25",BookingRaw!$B$2:$B$600,">="&Control!$B$9,BookingRaw!$B$2:$B$600,"<="&Control!$C$4) -> 0 | E9: =SUMIFS(BookingRaw!$E$2:$E$600,BookingRaw!$A$2:$A$600,"BKK25",BookingRaw!$B$2:$B$600,">="&Control!$B$9,BookingRaw!$B$2:$B$600,"<="&Control!$C$4) -> 0 | F9: =SUMIFS(BookingRaw!$F$2:$F$600,BookingRaw!$A$2:$A$600,"BKK25",BookingRaw!$B$2:$B$600,">="&Control!$B$9,BookingRaw!$B$2:$B$600,"<="&Control!$C$4) -> 0 | G9: =SUMIFS(BookingRaw!$G$2:$G$600,BookingRaw!$A$2:$A$600,"BKK25",BookingRaw!$B$2:$B$600,">="&Control!$B$9,BookingRaw!$B$2:$B$600,"<="&Control!$C$4) -> 0 | H9: =SUMIFS(BookingRaw!$H$2:$H$600,BookingRaw!$A$2:$A$600,"BKK25",BookingRaw!$B$2:$B$600,">="&Control!$B$9,BookingRaw!$B$2:$B$600,"<="&Control!$C$4) -> 0 | I9: =SUMIFS(BookingRaw!$I$2:$I$600,BookingRaw!$A$2:$A$600,"BKK25",BookingRaw!$B$2:$B$600,">="&Control!$B$9,BookingRaw!$B$2:$B$600,"<="&Control!$C$4) -> 0 | J9: =SUMIFS(BookingRaw!$J$2:$J$600,BookingRaw!$A$2:$A$600,"BKK25",BookingRaw!$B$2:$B$600,">="&Control!$B$9,BookingRaw!$B$2:$B$600,"<="&Control!$C$4) -> 0 | K9: =SUMIFS(BookingRaw!$K$2:$K$600,BookingRaw!$A$2:$A$600,"BKK25",BookingRaw!$B$2:$B$600,">="&Control!$B$9,BookingRaw!$B$2:$B$600,"<="&Control!$C$4) -> 0 | M9: =Control!$A$4 -> 37 | N9: =IF(Control!$B$9=Control!$C$4,DAY(Control!$B$9)&" "&CHOOSE(MONTH(Control!$B$9),"Jan","Feb","Mar","Apr","May","Jun","Jul","Aug","Sep","Oct","Nov","Dec"),"Booking on "&IF(MONTH(Control!$B$9)=MONTH(Control!$C$4),DAY(Control!$B$9)&"-"&DAY(Control!$C$4)&" "&CHOOSE(MONTH(Control!$C$4),"Jan","Feb","Mar","Apr","May","Jun","Jul","Aug","Sep","Oct","Nov","Dec"),DAY(Control!$B$9)&" "&CHOOSE(MONTH(Control!$B$9),"Jan","Feb","Mar","Apr","May","Jun","Jul","Aug","Sep","Oct","Nov","Dec")&"-"&DAY(Control!$C$4)&" "&CHOOSE(MONTH(Control!$C$4),"Jan","Feb","Mar","Apr","May","Jun","Jul","Aug","Sep","Oct","Nov","Dec"))) -> Booking on 11-12 Sep | O9: =SUMIFS(BookingRaw!$C$2:$C$600,BookingRaw!$A$2:$A$600,"BKK01",BookingRaw!$B$2:$B$600,">="&Control!$B$9,BookingRaw!$B$2:$B$600,"<="&Control!$C$4) -> 0 | P9: =SUMIFS(BookingRaw!$D$2:$D$600,BookingRaw!$A$2:$A$600,"BKK01",BookingRaw!$B$2:$B$600,">="&Control!$B$9,BookingRaw!$B$2:$B$600,"<="&Control!$C$4) -> 0 | Q9: =SUMIFS(BookingRaw!$E$2:$E$600,BookingRaw!$A$2:$A$600,"BKK01",BookingRaw!$B$2:$B$600,">="&Control!$B$9,BookingRaw!$B$2:$B$600,"<="&Control!$C$4) -> 0 | R9: =SUMIFS(BookingRaw!$F$2:$F$600,BookingRaw!$A$2:$A$600,"BKK01",BookingRaw!$B$2:$B$600,">="&Control!$B$9,BookingRaw!$B$2:$B$600,"<="&Control!$C$4) -> 0 | S9: =SUMIFS(BookingRaw!$G$2:$G$600,BookingRaw!$A$2:$A$600,"BKK01",BookingRaw!$B$2:$B$600,">="&Control!$B$9,BookingRaw!$B$2:$B$600,"<="&Control!$C$4) -> 0 | T9: =SUMIFS(BookingRaw!$H$2:$H$600,BookingRaw!$A$2:$A$600,"BKK01",BookingRaw!$B$2:$B$600,">="&Control!$B$9,BookingRaw!$B$2:$B$600,"<="&Control!$C$4) -> 0 | U9: =SUMIFS(BookingRaw!$I$2:$I$600,BookingRaw!$A$2:$A$600,"BKK01",BookingRaw!$B$2:$B$600,">="&Control!$B$9,BookingRaw!$B$2:$B$600,"<="&Control!$C$4) -> 0 | V9: =SUMIFS(BookingRaw!$J$2:$J$600,BookingRaw!$A$2:$A$600,"BKK01",BookingRaw!$B$2:$B$600,">="&Control!$B$9,BookingRaw!$B$2:$B$600,"<="&Control!$C$4) -> 0 | W9: =SUMIFS(BookingRaw!$K$2:$K$600,BookingRaw!$A$2:$A$600,"BKK01",BookingRaw!$B$2:$B$600,">="&Control!$B$9,BookingRaw!$B$2:$B$600,"<="&Control!$C$4) -> 0 | Y9: =Control!$A$4 -> 37 | Z9: =IF(Control!$B$9=Control!$C$4,DAY(Control!$B$9)&" "&CHOOSE(MONTH(Control!$B$9),"Jan","Feb","Mar","Apr","May","Jun","Jul","Aug","Sep","Oct","Nov","Dec"),"Booking on "&IF(MONTH(Control!$B$9)=MONTH(Control!$C$4),DAY(Control!$B$9)&"-"&DAY(Control!$C$4)&" "&CHOOSE(MONTH(Control!$C$4),"Jan","Feb","Mar","Apr","May","Jun","Jul","Aug","Sep","Oct","Nov","Dec"),DAY(Control!$B$9)&" "&CHOOSE(MONTH(Control!$B$9),"Jan","Feb","Mar","Apr","May","Jun","Jul","Aug","Sep","Oct","Nov","Dec")&"-"&DAY(Control!$C$4)&" "&CHOOSE(MONTH(Control!$C$4),"Jan","Feb","Mar","Apr","May","Jun","Jul","Aug","Sep","Oct","Nov","Dec"))) -> Booking on 11-12 Sep | AA9: =SUMIFS(BookingRaw!$C$2:$C$600,BookingRaw!$A$2:$A$600,"LCH27",BookingRaw!$B$2:$B$600,">="&Control!$B$9,BookingRaw!$B$2:$B$600,"<="&Control!$C$4) -> 0 | AB9: =SUMIFS(BookingRaw!$D$2:$D$600,BookingRaw!$A$2:$A$600,"LCH27",BookingRaw!$B$2:$B$600,">="&Control!$B$9,BookingRaw!$B$2:$B$600,"<="&Control!$C$4) -> 0 | AC9: =SUMIFS(BookingRaw!$E$2:$E$600,BookingRaw!$A$2:$A$600,"LCH27",BookingRaw!$B$2:$B$600,">="&Control!$B$9,BookingRaw!$B$2:$B$600,"<="&Control!$C$4) -> 0 | AD9: =SUMIFS(BookingRaw!$F$2:$F$600,BookingRaw!$A$2:$A$600,"LCH27",BookingRaw!$B$2:$B$600,">="&Control!$B$9,BookingRaw!$B$2:$B$600,"<="&Control!$C$4) -> 0 | AE9: =SUMIFS(BookingRaw!$G$2:$G$600,BookingRaw!$A$2:$A$600,"LCH27",BookingRaw!$B$2:$B$600,">="&Control!$B$9,BookingRaw!$B$2:$B$600,"<="&Control!$C$4) -> 2 | AF9: =SUMIFS(BookingRaw!$H$2:$H$600,BookingRaw!$A$2:$A$600,"LCH27",BookingRaw!$B$2:$B$600,">="&Control!$B$9,BookingRaw!$B$2:$B$600,"<="&Control!$C$4) -> 0 | AG9: =SUMIFS(BookingRaw!$I$2:$I$600,BookingRaw!$A$2:$A$600,"LCH27",BookingRaw!$B$2:$B$600,">="&Control!$B$9,BookingRaw!$B$2:$B$600,"<="&Control!$C$4) -> 0 | AH9: =SUMIFS(BookingRaw!$J$2:$J$600,BookingRaw!$A$2:$A$600,"LCH27",BookingRaw!$B$2:$B$600,">="&Control!$B$9,BookingRaw!$B$2:$B$600,"<="&Control!$C$4) -> 0 | AI9: =SUMIFS(BookingRaw!$K$2:$K$600,BookingRaw!$A$2:$A$600,"LCH27",BookingRaw!$B$2:$B$600,">="&Control!$B$9,BookingRaw!$B$2:$B$600,"<="&Control!$C$4) -> 0
B10: ="AV Balance till "&DAY(Control!$C$4)&" "&CHOOSE(MONTH(Control!$C$4),"Jan","Feb","Mar","Apr","May","Jun","Jul","Aug","Sep","Oct","Nov","Dec") -> AV Balance till 12 Sep | C10: =C6-C7-C8-C9 -> 0 | D10: =D6-D7-D8-D9 -> 0 | E10: =E6-E7-E8-E9 -> 0 | F10: =F6-F7-F8-F9 -> 0 | G10: =G6-G7-G8-G9 -> 0 | H10: =H6-H7-H8-H9 -> 0 | I10: =I6-I7-I8-I9 -> 0 | J10: =J6-J7-J8-J9 -> 0 | K10: =K6-K7-K8-K9 -> 0 | N10: ="AV Balance till "&DAY(Control!$C$4)&" "&CHOOSE(MONTH(Control!$C$4),"Jan","Feb","Mar","Apr","May","Jun","Jul","Aug","Sep","Oct","Nov","Dec") -> AV Balance till 12 Sep | O10: =O6-O7-O8-O9 -> 0 | P10: =P6-P7-P8-P9 -> 0 | Q10: =Q6-Q7-Q8-Q9 -> 0 | R10: =R6-R7-R8-R9 -> 0 | S10: =S6-S7-S8-S9 -> 0 | T10: =T6-T7-T8-T9 -> 0 | U10: =U6-U7-U8-U9 -> 0 | V10: =V6-V7-V8-V9 -> 0 | W10: =W6-W7-W8-W9 -> 0 | Z10: ="AV Balance till "&DAY(Control!$C$4)&" "&CHOOSE(MONTH(Control!$C$4),"Jan","Feb","Mar","Apr","May","Jun","Jul","Aug","Sep","Oct","Nov","Dec") -> AV Balance till 12 Sep | AA10: =AA6-AA7-AA8-AA9 -> 0 | AB10: =AB6-AB7-AB8-AB9 -> 0 | AC10: =AC6-AC7-AC8-AC9 -> 0 | AD10: =AD6-AD7-AD8-AD9 -> 6 | AE10: =AE6-AE7-AE8-AE9 -> 55 | AF10: =AF6-AF7-AF8-AF9 -> 0 | AG10: =AG6-AG7-AG8-AG9 -> 0 | AH10: =AH6-AH7-AH8-AH9 -> 0 | AI10: =AI6-AI7-AI8-AI9 -> 0
A11: =Control!$A$5 -> 38 | B11: ="Booking on "&IF(MONTH(Control!$B$5)=MONTH(Control!$C$5),DAY(Control!$B$5)&"-"&DAY(Control!$C$5)&" "&CHOOSE(MONTH(Control!$C$5),"Jan","Feb","Mar","Apr","May","Jun","Jul","Aug","Sep","Oct","Nov","Dec"),DAY(Control!$B$5)&" "&CHOOSE(MONTH(Control!$B$5),"Jan","Feb","Mar","Apr","May","Jun","Jul","Aug","Sep","Oct","Nov","Dec")&"-"&DAY(Control!$C$5)&" "&CHOOSE(MONTH(Control!$C$5),"Jan","Feb","Mar","Apr","May","Jun","Jul","Aug","Sep","Oct","Nov","Dec")) -> Booking on 14-19 Sep | C11: =SUMIFS(BookingRaw!$C$2:$C$600,BookingRaw!$A$2:$A$600,"BKK25",BookingRaw!$B$2:$B$600,">="&Control!$B$5,BookingRaw!$B$2:$B$600,"<="&Control!$C$5) -> 0 | D11: =SUMIFS(BookingRaw!$D$2:$D$600,BookingRaw!$A$2:$A$600,"BKK25",BookingRaw!$B$2:$B$600,">="&Control!$B$5,BookingRaw!$B$2:$B$600,"<="&Control!$C$5) -> 0 | E11: =SUMIFS(BookingRaw!$E$2:$E$600,BookingRaw!$A$2:$A$600,"BKK25",BookingRaw!$B$2:$B$600,">="&Control!$B$5,BookingRaw!$B$2:$B$600,"<="&Control!$C$5) -> 0 | F11: =SUMIFS(BookingRaw!$F$2:$F$600,BookingRaw!$A$2:$A$600,"BKK25",BookingRaw!$B$2:$B$600,">="&Control!$B$5,BookingRaw!$B$2:$B$600,"<="&Control!$C$5) -> 0 | G11: =SUMIFS(BookingRaw!$G$2:$G$600,BookingRaw!$A$2:$A$600,"BKK25",BookingRaw!$B$2:$B$600,">="&Control!$B$5,BookingRaw!$B$2:$B$600,"<="&Control!$C$5) -> 0 | H11: =SUMIFS(BookingRaw!$H$2:$H$600,BookingRaw!$A$2:$A$600,"BKK25",BookingRaw!$B$2:$B$600,">="&Control!$B$5,BookingRaw!$B$2:$B$600,"<="&Control!$C$5) -> 0 | I11: =SUMIFS(BookingRaw!$I$2:$I$600,BookingRaw!$A$2:$A$600,"BKK25",BookingRaw!$B$2:$B$600,">="&Control!$B$5,BookingRaw!$B$2:$B$600,"<="&Control!$C$5) -> 0 | J11: =SUMIFS(BookingRaw!$J$2:$J$600,BookingRaw!$A$2:$A$600,"BKK25",BookingRaw!$B$2:$B$600,">="&Control!$B$5,BookingRaw!$B$2:$B$600,"<="&Control!$C$5) -> 0 | K11: =SUMIFS(BookingRaw!$K$2:$K$600,BookingRaw!$A$2:$A$600,"BKK25",BookingRaw!$B$2:$B$600,">="&Control!$B$5,BookingRaw!$B$2:$B$600,"<="&Control!$C$5) -> 0 | M11: =Control!$A$5 -> 38 | N11: ="Booking on "&IF(MONTH(Control!$B$5)=MONTH(Control!$C$5),DAY(Control!$B$5)&"-"&DAY(Control!$C$5)&" "&CHOOSE(MONTH(Control!$C$5),"Jan","Feb","Mar","Apr","May","Jun","Jul","Aug","Sep","Oct","Nov","Dec"),DAY(Control!$B$5)&" "&CHOOSE(MONTH(Control!$B$5),"Jan","Feb","Mar","Apr","May","Jun","Jul","Aug","Sep","Oct","Nov","Dec")&"-"&DAY(Control!$C$5)&" "&CHOOSE(MONTH(Control!$C$5),"Jan","Feb","Mar","Apr","May","Jun","Jul","Aug","Sep","Oct","Nov","Dec")) -> Booking on 14-19 Sep | O11: =SUMIFS(BookingRaw!$C$2:$C$600,BookingRaw!$A$2:$A$600,"BKK01",BookingRaw!$B$2:$B$600,">="&Control!$B$5,BookingRaw!$B$2:$B$600,"<="&Control!$C$5) -> 0 | P11: =SUMIFS(BookingRaw!$D$2:$D$600,BookingRaw!$A$2:$A$600,"BKK01",BookingRaw!$B$2:$B$600,">="&Control!$B$5,BookingRaw!$B$2:$B$600,"<="&Control!$C$5) -> 0 | Q11: =SUMIFS(BookingRaw!$E$2:$E$600,BookingRaw!$A$2:$A$600,"BKK01",BookingRaw!$B$2:$B$600,">="&Control!$B$5,BookingRaw!$B$2:$B$600,"<="&Control!$C$5) -> 0 | R11: =SUMIFS(BookingRaw!$F$2:$F$600,BookingRaw!$A$2:$A$600,"BKK01",BookingRaw!$B$2:$B$600,">="&Control!$B$5,BookingRaw!$B$2:$B$600,"<="&Control!$C$5) -> 0 | S11: =SUMIFS(BookingRaw!$G$2:$G$600,BookingRaw!$A$2:$A$600,"BKK01",BookingRaw!$B$2:$B$600,">="&Control!$B$5,BookingRaw!$B$2:$B$600,"<="&Control!$C$5) -> 0 | T11: =SUMIFS(BookingRaw!$H$2:$H$600,BookingRaw!$A$2:$A$600,"BKK01",BookingRaw!$B$2:$B$600,">="&Control!$B$5,BookingRaw!$B$2:$B$600,"<="&Control!$C$5) -> 0 | U11: =SUMIFS(BookingRaw!$I$2:$I$600,BookingRaw!$A$2:$A$600,"BKK01",BookingRaw!$B$2:$B$600,">="&Control!$B$5,BookingRaw!$B$2:$B$600,"<="&Control!$C$5) -> 0 | V11: =SUMIFS(BookingRaw!$J$2:$J$600,BookingRaw!$A$2:$A$600,"BKK01",BookingRaw!$B$2:$B$600,">="&Control!$B$5,BookingRaw!$B$2:$B$600,"<="&Control!$C$5) -> 0 | W11: =SUMIFS(BookingRaw!$K$2:$K$600,BookingRaw!$A$2:$A$600,"BKK01",BookingRaw!$B$2:$B$600,">="&Control!$B$5,BookingRaw!$B$2:$B$600,"<="&Control!$C$5) -> 0 | Y11: =Control!$A$5 -> 38 | Z11: ="Booking on "&IF(MONTH(Control!$B$5)=MONTH(Control!$C$5),DAY(Control!$B$5)&"-"&DAY(Control!$C$5)&" "&CHOOSE(MONTH(Control!$C$5),"Jan","Feb","Mar","Apr","May","Jun","Jul","Aug","Sep","Oct","Nov","Dec"),DAY(Control!$B$5)&" "&CHOOSE(MONTH(Control!$B$5),"Jan","Feb","Mar","Apr","May","Jun","Jul","Aug","Sep","Oct","Nov","Dec")&"-"&DAY(Control!$C$5)&" "&CHOOSE(MONTH(Control!$C$5),"Jan","Feb","Mar","Apr","May","Jun","Jul","Aug","Sep","Oct","Nov","Dec")) -> Booking on 14-19 Sep | AA11: =SUMIFS(BookingRaw!$C$2:$C$600,BookingRaw!$A$2:$A$600,"LCH27",BookingRaw!$B$2:$B$600,">="&Control!$B$5,BookingRaw!$B$2:$B$600,"<="&Control!$C$5) -> 0 | AB11: =SUMIFS(BookingRaw!$D$2:$D$600,BookingRaw!$A$2:$A$600,"LCH27",BookingRaw!$B$2:$B$600,">="&Control!$B$5,BookingRaw!$B$2:$B$600,"<="&Control!$C$5) -> 0 | AC11: =SUMIFS(BookingRaw!$E$2:$E$600,BookingRaw!$A$2:$A$600,"LCH27",BookingRaw!$B$2:$B$600,">="&Control!$B$5,BookingRaw!$B$2:$B$600,"<="&Control!$C$5) -> 0 | AD11: =SUMIFS(BookingRaw!$F$2:$F$600,BookingRaw!$A$2:$A$600,"LCH27",BookingRaw!$B$2:$B$600,">="&Control!$B$5,BookingRaw!$B$2:$B$600,"<="&Control!$C$5) -> 1 | AE11: =SUMIFS(BookingRaw!$G$2:$G$600,BookingRaw!$A$2:$A$600,"LCH27",BookingRaw!$B$2:$B$600,">="&Control!$B$5,BookingRaw!$B$2:$B$600,"<="&Control!$C$5) -> 31 | AF11: =SUMIFS(BookingRaw!$H$2:$H$600,BookingRaw!$A$2:$A$600,"LCH27",BookingRaw!$B$2:$B$600,">="&Control!$B$5,BookingRaw!$B$2:$B$600,"<="&Control!$C$5) -> 0 | AG11: =SUMIFS(BookingRaw!$I$2:$I$600,BookingRaw!$A$2:$A$600,"LCH27",BookingRaw!$B$2:$B$600,">="&Control!$B$5,BookingRaw!$B$2:$B$600,"<="&Control!$C$5) -> 0 | AH11: =SUMIFS(BookingRaw!$J$2:$J$600,BookingRaw!$A$2:$A$600,"LCH27",BookingRaw!$B$2:$B$600,">="&Control!$B$5,BookingRaw!$B$2:$B$600,"<="&Control!$C$5) -> 0 | AI11: =SUMIFS(BookingRaw!$K$2:$K$600,BookingRaw!$A$2:$A$600,"LCH27",BookingRaw!$B$2:$B$600,">="&Control!$B$5,BookingRaw!$B$2:$B$600,"<="&Control!$C$5) -> 0
B12: ="AV Balance till "&DAY(Control!$C$5)&" "&CHOOSE(MONTH(Control!$C$5),"Jan","Feb","Mar","Apr","May","Jun","Jul","Aug","Sep","Oct","Nov","Dec") -> AV Balance till 19 Sep | C12: =C10-C11 -> 0 | D12: =D10-D11 -> 0 | E12: =E10-E11 -> 0 | F12: =F10-F11 -> 0 | G12: =G10-G11 -> 0 | H12: =H10-H11 -> 0 | I12: =I10-I11 -> 0 | J12: =J10-J11 -> 0 | K12: =K10-K11 -> 0 | N12: ="AV Balance till "&DAY(Control!$C$5)&" "&CHOOSE(MONTH(Control!$C$5),"Jan","Feb","Mar","Apr","May","Jun","Jul","Aug","Sep","Oct","Nov","Dec") -> AV Balance till 19 Sep | O12: =O10-O11 -> 0 | P12: =P10-P11 -> 0 | Q12: =Q10-Q11 -> 0 | R12: =R10-R11 -> 0 | S12: =S10-S11 -> 0 | T12: =T10-T11 -> 0 | U12: =U10-U11 -> 0 | V12: =V10-V11 -> 0 | W12: =W10-W11 -> 0 | Z12: ="AV Balance till "&DAY(Control!$C$5)&" "&CHOOSE(MONTH(Control!$C$5),"Jan","Feb","Mar","Apr","May","Jun","Jul","Aug","Sep","Oct","Nov","Dec") -> AV Balance till 19 Sep | AA12: =AA10-AA11 -> 0 | AB12: =AB10-AB11 -> 0 | AC12: =AC10-AC11 -> 0 | AD12: =AD10-AD11 -> 5 | AE12: =AE10-AE11 -> 24 | AF12: =AF10-AF11 -> 0 | AG12: =AG10-AG11 -> 0 | AH12: =AH10-AH11 -> 0 | AI12: =AI10-AI11 -> 0
A13: =Control!$A$6 -> 39 | B13: ="Booking on "&IF(MONTH(Control!$B$6)=MONTH(Control!$C$6),DAY(Control!$B$6)&"-"&DAY(Control!$C$6)&" "&CHOOSE(MONTH(Control!$C$6),"Jan","Feb","Mar","Apr","May","Jun","Jul","Aug","Sep","Oct","Nov","Dec"),DAY(Control!$B$6)&" "&CHOOSE(MONTH(Control!$B$6),"Jan","Feb","Mar","Apr","May","Jun","Jul","Aug","Sep","Oct","Nov","Dec")&"-"&DAY(Control!$C$6)&" "&CHOOSE(MONTH(Control!$C$6),"Jan","Feb","Mar","Apr","May","Jun","Jul","Aug","Sep","Oct","Nov","Dec")) -> Booking on 21-26 Sep | C13: =SUMIFS(BookingRaw!$C$2:$C$600,BookingRaw!$A$2:$A$600,"BKK25",BookingRaw!$B$2:$B$600,">="&Control!$B$6,BookingRaw!$B$2:$B$600,"<="&Control!$C$6) -> 0 | D13: =SUMIFS(BookingRaw!$D$2:$D$600,BookingRaw!$A$2:$A$600,"BKK25",BookingRaw!$B$2:$B$600,">="&Control!$B$6,BookingRaw!$B$2:$B$600,"<="&Control!$C$6) -> 0 | E13: =SUMIFS(BookingRaw!$E$2:$E$600,BookingRaw!$A$2:$A$600,"BKK25",BookingRaw!$B$2:$B$600,">="&Control!$B$6,BookingRaw!$B$2:$B$600,"<="&Control!$C$6) -> 0 | F13: =SUMIFS(BookingRaw!$F$2:$F$600,BookingRaw!$A$2:$A$600,"BKK25",BookingRaw!$B$2:$B$600,">="&Control!$B$6,BookingRaw!$B$2:$B$600,"<="&Control!$C$6) -> 0 | G13: =SUMIFS(BookingRaw!$G$2:$G$600,BookingRaw!$A$2:$A$600,"BKK25",BookingRaw!$B$2:$B$600,">="&Control!$B$6,BookingRaw!$B$2:$B$600,"<="&Control!$C$6) -> 0 | H13: =SUMIFS(BookingRaw!$H$2:$H$600,BookingRaw!$A$2:$A$600,"BKK25",BookingRaw!$B$2:$B$600,">="&Control!$B$6,BookingRaw!$B$2:$B$600,"<="&Control!$C$6) -> 0 | I13: =SUMIFS(BookingRaw!$I$2:$I$600,BookingRaw!$A$2:$A$600,"BKK25",BookingRaw!$B$2:$B$600,">="&Control!$B$6,BookingRaw!$B$2:$B$600,"<="&Control!$C$6) -> 0 | J13: =SUMIFS(BookingRaw!$J$2:$J$600,BookingRaw!$A$2:$A$600,"BKK25",BookingRaw!$B$2:$B$600,">="&Control!$B$6,BookingRaw!$B$2:$B$600,"<="&Control!$C$6) -> 0 | K13: =SUMIFS(BookingRaw!$K$2:$K$600,BookingRaw!$A$2:$A$600,"BKK25",BookingRaw!$B$2:$B$600,">="&Control!$B$6,BookingRaw!$B$2:$B$600,"<="&Control!$C$6) -> 0 | M13: =Control!$A$6 -> 39 | N13: ="Booking on "&IF(MONTH(Control!$B$6)=MONTH(Control!$C$6),DAY(Control!$B$6)&"-"&DAY(Control!$C$6)&" "&CHOOSE(MONTH(Control!$C$6),"Jan","Feb","Mar","Apr","May","Jun","Jul","Aug","Sep","Oct","Nov","Dec"),DAY(Control!$B$6)&" "&CHOOSE(MONTH(Control!$B$6),"Jan","Feb","Mar","Apr","May","Jun","Jul","Aug","Sep","Oct","Nov","Dec")&"-"&DAY(Control!$C$6)&" "&CHOOSE(MONTH(Control!$C$6),"Jan","Feb","Mar","Apr","May","Jun","Jul","Aug","Sep","Oct","Nov","Dec")) -> Booking on 21-26 Sep | O13: =SUMIFS(BookingRaw!$C$2:$C$600,BookingRaw!$A$2:$A$600,"BKK01",BookingRaw!$B$2:$B$600,">="&Control!$B$6,BookingRaw!$B$2:$B$600,"<="&Control!$C$6) -> 0 | P13: =SUMIFS(BookingRaw!$D$2:$D$600,BookingRaw!$A$2:$A$600,"BKK01",BookingRaw!$B$2:$B$600,">="&Control!$B$6,BookingRaw!$B$2:$B$600,"<="&Control!$C$6) -> 0 | Q13: =SUMIFS(BookingRaw!$E$2:$E$600,BookingRaw!$A$2:$A$600,"BKK01",BookingRaw!$B$2:$B$600,">="&Control!$B$6,BookingRaw!$B$2:$B$600,"<="&Control!$C$6) -> 0 | R13: =SUMIFS(BookingRaw!$F$2:$F$600,BookingRaw!$A$2:$A$600,"BKK01",BookingRaw!$B$2:$B$600,">="&Control!$B$6,BookingRaw!$B$2:$B$600,"<="&Control!$C$6) -> 0 | S13: =SUMIFS(BookingRaw!$G$2:$G$600,BookingRaw!$A$2:$A$600,"BKK01",BookingRaw!$B$2:$B$600,">="&Control!$B$6,BookingRaw!$B$2:$B$600,"<="&Control!$C$6) -> 0 | T13: =SUMIFS(BookingRaw!$H$2:$H$600,BookingRaw!$A$2:$A$600,"BKK01",BookingRaw!$B$2:$B$600,">="&Control!$B$6,BookingRaw!$B$2:$B$600,"<="&Control!$C$6) -> 0 | U13: =SUMIFS(BookingRaw!$I$2:$I$600,BookingRaw!$A$2:$A$600,"BKK01",BookingRaw!$B$2:$B$600,">="&Control!$B$6,BookingRaw!$B$2:$B$600,"<="&Control!$C$6) -> 0 | V13: =SUMIFS(BookingRaw!$J$2:$J$600,BookingRaw!$A$2:$A$600,"BKK01",BookingRaw!$B$2:$B$600,">="&Control!$B$6,BookingRaw!$B$2:$B$600,"<="&Control!$C$6) -> 0 | W13: =SUMIFS(BookingRaw!$K$2:$K$600,BookingRaw!$A$2:$A$600,"BKK01",BookingRaw!$B$2:$B$600,">="&Control!$B$6,BookingRaw!$B$2:$B$600,"<="&Control!$C$6) -> 0 | Y13: =Control!$A$6 -> 39 | Z13: ="Booking on "&IF(MONTH(Control!$B$6)=MONTH(Control!$C$6),DAY(Control!$B$6)&"-"&DAY(Control!$C$6)&" "&CHOOSE(MONTH(Control!$C$6),"Jan","Feb","Mar","Apr","May","Jun","Jul","Aug","Sep","Oct","Nov","Dec"),DAY(Control!$B$6)&" "&CHOOSE(MONTH(Control!$B$6),"Jan","Feb","Mar","Apr","May","Jun","Jul","Aug","Sep","Oct","Nov","Dec")&"-"&DAY(Control!$C$6)&" "&CHOOSE(MONTH(Control!$C$6),"Jan","Feb","Mar","Apr","May","Jun","Jul","Aug","Sep","Oct","Nov","Dec")) -> Booking on 21-26 Sep | AA13: =SUMIFS(BookingRaw!$C$2:$C$600,BookingRaw!$A$2:$A$600,"LCH27",BookingRaw!$B$2:$B$600,">="&Control!$B$6,BookingRaw!$B$2:$B$600,"<="&Control!$C$6) -> 0 | AB13: =SUMIFS(BookingRaw!$D$2:$D$600,BookingRaw!$A$2:$A$600,"LCH27",BookingRaw!$B$2:$B$600,">="&Control!$B$6,BookingRaw!$B$2:$B$600,"<="&Control!$C$6) -> 0 | AC13: =SUMIFS(BookingRaw!$E$2:$E$600,BookingRaw!$A$2:$A$600,"LCH27",BookingRaw!$B$2:$B$600,">="&Control!$B$6,BookingRaw!$B$2:$B$600,"<="&Control!$C$6) -> 0 | AD13: =SUMIFS(BookingRaw!$F$2:$F$600,BookingRaw!$A$2:$A$600,"LCH27",BookingRaw!$B$2:$B$600,">="&Control!$B$6,BookingRaw!$B$2:$B$600,"<="&Control!$C$6) -> 1 | AE13: =SUMIFS(BookingRaw!$G$2:$G$600,BookingRaw!$A$2:$A$600,"LCH27",BookingRaw!$B$2:$B$600,">="&Control!$B$6,BookingRaw!$B$2:$B$600,"<="&Control!$C$6) -> 1 | AF13: =SUMIFS(BookingRaw!$H$2:$H$600,BookingRaw!$A$2:$A$600,"LCH27",BookingRaw!$B$2:$B$600,">="&Control!$B$6,BookingRaw!$B$2:$B$600,"<="&Control!$C$6) -> 0 | AG13: =SUMIFS(BookingRaw!$I$2:$I$600,BookingRaw!$A$2:$A$600,"LCH27",BookingRaw!$B$2:$B$600,">="&Control!$B$6,BookingRaw!$B$2:$B$600,"<="&Control!$C$6) -> 0 | AH13: =SUMIFS(BookingRaw!$J$2:$J$600,BookingRaw!$A$2:$A$600,"LCH27",BookingRaw!$B$2:$B$600,">="&Control!$B$6,BookingRaw!$B$2:$B$600,"<="&Control!$C$6) -> 0 | AI13: =SUMIFS(BookingRaw!$K$2:$K$600,BookingRaw!$A$2:$A$600,"LCH27",BookingRaw!$B$2:$B$600,">="&Control!$B$6,BookingRaw!$B$2:$B$600,"<="&Control!$C$6) -> 0
B14: ="AV Balance till "&DAY(Control!$C$6)&" "&CHOOSE(MONTH(Control!$C$6),"Jan","Feb","Mar","Apr","May","Jun","Jul","Aug","Sep","Oct","Nov","Dec") -> AV Balance till 26 Sep | C14: =C12-C13 -> 0 | D14: =D12-D13 -> 0 | E14: =E12-E13 -> 0 | F14: =F12-F13 -> 0 | G14: =G12-G13 -> 0 | H14: =H12-H13 -> 0 | I14: =I12-I13 -> 0 | J14: =J12-J13 -> 0 | K14: =K12-K13 -> 0 | N14: ="AV Balance till "&DAY(Control!$C$6)&" "&CHOOSE(MONTH(Control!$C$6),"Jan","Feb","Mar","Apr","May","Jun","Jul","Aug","Sep","Oct","Nov","Dec") -> AV Balance till 26 Sep | O14: =O12-O13 -> 0 | P14: =P12-P13 -> 0 | Q14: =Q12-Q13 -> 0 | R14: =R12-R13 -> 0 | S14: =S12-S13 -> 0 | T14: =T12-T13 -> 0 | U14: =U12-U13 -> 0 | V14: =V12-V13 -> 0 | W14: =W12-W13 -> 0 | Z14: ="AV Balance till "&DAY(Control!$C$6)&" "&CHOOSE(MONTH(Control!$C$6),"Jan","Feb","Mar","Apr","May","Jun","Jul","Aug","Sep","Oct","Nov","Dec") -> AV Balance till 26 Sep | AA14: =AA12-AA13 -> 0 | AB14: =AB12-AB13 -> 0 | AC14: =AC12-AC13 -> 0 | AD14: =AD12-AD13 -> 4 | AE14: =AE12-AE13 -> 23 | AF14: =AF12-AF13 -> 0 | AG14: =AG12-AG13 -> 0 | AH14: =AH12-AH13 -> 0 | AI14: =AI12-AI13 -> 0
A15: =Control!$A$7 -> 40 | B15: ="Booking on "&IF(MONTH(Control!$B$7)=MONTH(Control!$C$7),DAY(Control!$B$7)&"-"&DAY(Control!$C$7)&" "&CHOOSE(MONTH(Control!$C$7),"Jan","Feb","Mar","Apr","May","Jun","Jul","Aug","Sep","Oct","Nov","Dec"),DAY(Control!$B$7)&" "&CHOOSE(MONTH(Control!$B$7),"Jan","Feb","Mar","Apr","May","Jun","Jul","Aug","Sep","Oct","Nov","Dec")&"-"&DAY(Control!$C$7)&" "&CHOOSE(MONTH(Control!$C$7),"Jan","Feb","Mar","Apr","May","Jun","Jul","Aug","Sep","Oct","Nov","Dec")) -> Booking on 28 Sep-3 Oct | C15: =SUMIFS(BookingRaw!$C$2:$C$600,BookingRaw!$A$2:$A$600,"BKK25",BookingRaw!$B$2:$B$600,">="&Control!$B$7,BookingRaw!$B$2:$B$600,"<="&Control!$C$7) -> 0 | D15: =SUMIFS(BookingRaw!$D$2:$D$600,BookingRaw!$A$2:$A$600,"BKK25",BookingRaw!$B$2:$B$600,">="&Control!$B$7,BookingRaw!$B$2:$B$600,"<="&Control!$C$7) -> 0 | E15: =SUMIFS(BookingRaw!$E$2:$E$600,BookingRaw!$A$2:$A$600,"BKK25",BookingRaw!$B$2:$B$600,">="&Control!$B$7,BookingRaw!$B$2:$B$600,"<="&Control!$C$7) -> 0 | F15: =SUMIFS(BookingRaw!$F$2:$F$600,BookingRaw!$A$2:$A$600,"BKK25",BookingRaw!$B$2:$B$600,">="&Control!$B$7,BookingRaw!$B$2:$B$600,"<="&Control!$C$7) -> 0 | G15: =SUMIFS(BookingRaw!$G$2:$G$600,BookingRaw!$A$2:$A$600,"BKK25",BookingRaw!$B$2:$B$600,">="&Control!$B$7,BookingRaw!$B$2:$B$600,"<="&Control!$C$7) -> 0 | H15: =SUMIFS(BookingRaw!$H$2:$H$600,BookingRaw!$A$2:$A$600,"BKK25",BookingRaw!$B$2:$B$600,">="&Control!$B$7,BookingRaw!$B$2:$B$600,"<="&Control!$C$7) -> 0 | I15: =SUMIFS(BookingRaw!$I$2:$I$600,BookingRaw!$A$2:$A$600,"BKK25",BookingRaw!$B$2:$B$600,">="&Control!$B$7,BookingRaw!$B$2:$B$600,"<="&Control!$C$7) -> 0 | J15: =SUMIFS(BookingRaw!$J$2:$J$600,BookingRaw!$A$2:$A$600,"BKK25",BookingRaw!$B$2:$B$600,">="&Control!$B$7,BookingRaw!$B$2:$B$600,"<="&Control!$C$7) -> 0 | K15: =SUMIFS(BookingRaw!$K$2:$K$600,BookingRaw!$A$2:$A$600,"BKK25",BookingRaw!$B$2:$B$600,">="&Control!$B$7,BookingRaw!$B$2:$B$600,"<="&Control!$C$7) -> 0 | M15: =Control!$A$7 -> 40 | N15: ="Booking on "&IF(MONTH(Control!$B$7)=MONTH(Control!$C$7),DAY(Control!$B$7)&"-"&DAY(Control!$C$7)&" "&CHOOSE(MONTH(Control!$C$7),"Jan","Feb","Mar","Apr","May","Jun","Jul","Aug","Sep","Oct","Nov","Dec"),DAY(Control!$B$7)&" "&CHOOSE(MONTH(Control!$B$7),"Jan","Feb","Mar","Apr","May","Jun","Jul","Aug","Sep","Oct","Nov","Dec")&"-"&DAY(Control!$C$7)&" "&CHOOSE(MONTH(Control!$C$7),"Jan","Feb","Mar","Apr","May","Jun","Jul","Aug","Sep","Oct","Nov","Dec")) -> Booking on 28 Sep-3 Oct | O15: =SUMIFS(BookingRaw!$C$2:$C$600,BookingRaw!$A$2:$A$600,"BKK01",BookingRaw!$B$2:$B$600,">="&Control!$B$7,BookingRaw!$B$2:$B$600,"<="&Control!$C$7) -> 0 | P15: =SUMIFS(BookingRaw!$D$2:$D$600,BookingRaw!$A$2:$A$600,"BKK01",BookingRaw!$B$2:$B$600,">="&Control!$B$7,BookingRaw!$B$2:$B$600,"<="&Control!$C$7) -> 0 | Q15: =SUMIFS(BookingRaw!$E$2:$E$600,BookingRaw!$A$2:$A$600,"BKK01",BookingRaw!$B$2:$B$600,">="&Control!$B$7,BookingRaw!$B$2:$B$600,"<="&Control!$C$7) -> 0 | R15: =SUMIFS(BookingRaw!$F$2:$F$600,BookingRaw!$A$2:$A$600,"BKK01",BookingRaw!$B$2:$B$600,">="&Control!$B$7,BookingRaw!$B$2:$B$600,"<="&Control!$C$7) -> 0 | S15: =SUMIFS(BookingRaw!$G$2:$G$600,BookingRaw!$A$2:$A$600,"BKK01",BookingRaw!$B$2:$B$600,">="&Control!$B$7,BookingRaw!$B$2:$B$600,"<="&Control!$C$7) -> 0 | T15: =SUMIFS(BookingRaw!$H$2:$H$600,BookingRaw!$A$2:$A$600,"BKK01",BookingRaw!$B$2:$B$600,">="&Control!$B$7,BookingRaw!$B$2:$B$600,"<="&Control!$C$7) -> 0 | U15: =SUMIFS(BookingRaw!$I$2:$I$600,BookingRaw!$A$2:$A$600,"BKK01",BookingRaw!$B$2:$B$600,">="&Control!$B$7,BookingRaw!$B$2:$B$600,"<="&Control!$C$7) -> 0 | V15: =SUMIFS(BookingRaw!$J$2:$J$600,BookingRaw!$A$2:$A$600,"BKK01",BookingRaw!$B$2:$B$600,">="&Control!$B$7,BookingRaw!$B$2:$B$600,"<="&Control!$C$7) -> 0 | W15: =SUMIFS(BookingRaw!$K$2:$K$600,BookingRaw!$A$2:$A$600,"BKK01",BookingRaw!$B$2:$B$600,">="&Control!$B$7,BookingRaw!$B$2:$B$600,"<="&Control!$C$7) -> 0 | Y15: =Control!$A$7 -> 40 | Z15: ="Booking on "&IF(MONTH(Control!$B$7)=MONTH(Control!$C$7),DAY(Control!$B$7)&"-"&DAY(Control!$C$7)&" "&CHOOSE(MONTH(Control!$C$7),"Jan","Feb","Mar","Apr","May","Jun","Jul","Aug","Sep","Oct","Nov","Dec"),DAY(Control!$B$7)&" "&CHOOSE(MONTH(Control!$B$7),"Jan","Feb","Mar","Apr","May","Jun","Jul","Aug","Sep","Oct","Nov","Dec")&"-"&DAY(Control!$C$7)&" "&CHOOSE(MONTH(Control!$C$7),"Jan","Feb","Mar","Apr","May","Jun","Jul","Aug","Sep","Oct","Nov","Dec")) -> Booking on 28 Sep-3 Oct | AA15: =SUMIFS(BookingRaw!$C$2:$C$600,BookingRaw!$A$2:$A$600,"LCH27",BookingRaw!$B$2:$B$600,">="&Control!$B$7,BookingRaw!$B$2:$B$600,"<="&Control!$C$7) -> 0 | AB15: =SUMIFS(BookingRaw!$D$2:$D$600,BookingRaw!$A$2:$A$600,"LCH27",BookingRaw!$B$2:$B$600,">="&Control!$B$7,BookingRaw!$B$2:$B$600,"<="&Control!$C$7) -> 0 | AC15: =SUMIFS(BookingRaw!$E$2:$E$600,BookingRaw!$A$2:$A$600,"LCH27",BookingRaw!$B$2:$B$600,">="&Control!$B$7,BookingRaw!$B$2:$B$600,"<="&Control!$C$7) -> 0 | AD15: =SUMIFS(BookingRaw!$F$2:$F$600,BookingRaw!$A$2:$A$600,"LCH27",BookingRaw!$B$2:$B$600,">="&Control!$B$7,BookingRaw!$B$2:$B$600,"<="&Control!$C$7) -> 0 | AE15: =SUMIFS(BookingRaw!$G$2:$G$600,BookingRaw!$A$2:$A$600,"LCH27",BookingRaw!$B$2:$B$600,">="&Control!$B$7,BookingRaw!$B$2:$B$600,"<="&Control!$C$7) -> 0 | AF15: =SUMIFS(BookingRaw!$H$2:$H$600,BookingRaw!$A$2:$A$600,"LCH27",BookingRaw!$B$2:$B$600,">="&Control!$B$7,BookingRaw!$B$2:$B$600,"<="&Control!$C$7) -> 0 | AG15: =SUMIFS(BookingRaw!$I$2:$I$600,BookingRaw!$A$2:$A$600,"LCH27",BookingRaw!$B$2:$B$600,">="&Control!$B$7,BookingRaw!$B$2:$B$600,"<="&Control!$C$7) -> 0 | AH15: =SUMIFS(BookingRaw!$J$2:$J$600,BookingRaw!$A$2:$A$600,"LCH27",BookingRaw!$B$2:$B$600,">="&Control!$B$7,BookingRaw!$B$2:$B$600,"<="&Control!$C$7) -> 0 | AI15: =SUMIFS(BookingRaw!$K$2:$K$600,BookingRaw!$A$2:$A$600,"LCH27",BookingRaw!$B$2:$B$600,">="&Control!$B$7,BookingRaw!$B$2:$B$600,"<="&Control!$C$7) -> 0
B16: ="AV Balance till "&DAY(Control!$C$7)&" "&CHOOSE(MONTH(Control!$C$7),"Jan","Feb","Mar","Apr","May","Jun","Jul","Aug","Sep","Oct","Nov","Dec") -> AV Balance till 3 Oct | C16: =C14-C15 -> 0 | D16: =D14-D15 -> 0 | E16: =E14-E15 -> 0 | F16: =F14-F15 -> 0 | G16: =G14-G15 -> 0 | H16: =H14-H15 -> 0 | I16: =I14-I15 -> 0 | J16: =J14-J15 -> 0 | K16: =K14-K15 -> 0 | N16: ="AV Balance till "&DAY(Control!$C$7)&" "&CHOOSE(MONTH(Control!$C$7),"Jan","Feb","Mar","Apr","May","Jun","Jul","Aug","Sep","Oct","Nov","Dec") -> AV Balance till 3 Oct | O16: =O14-O15 -> 0 | P16: =P14-P15 -> 0 | Q16: =Q14-Q15 -> 0 | R16: =R14-R15 -> 0 | S16: =S14-S15 -> 0 | T16: =T14-T15 -> 0 | U16: =U14-U15 -> 0 | V16: =V14-V15 -> 0 | W16: =W14-W15 -> 0 | Z16: ="AV Balance till "&DAY(Control!$C$7)&" "&CHOOSE(MONTH(Control!$C$7),"Jan","Feb","Mar","Apr","May","Jun","Jul","Aug","Sep","Oct","Nov","Dec") -> AV Balance till 3 Oct | AA16: =AA14-AA15 -> 0 | AB16: =AB14-AB15 -> 0 | AC16: =AC14-AC15 -> 0 | AD16: =AD14-AD15 -> 4 | AE16: =AE14-AE15 -> 23 | AF16: =AF14-AF15 -> 0 | AG16: =AG14-AG15 -> 0 | AH16: =AH14-AH15 -> 0 | AI16: =AI14-AI15 -> 0
A17: BKK27 | M17: BKK02 | Y17: LCH28
A18: WK | C18: 20'GP | D18: 40'GP | E18: 40'HC | F18: 20'RE | G18: 40'RH | H18: 20'OT | I18: 40'OT | J18: 20'FR | K18: 40'FR | M18: WK | O18: 20'GP | P18: 40'GP | Q18: 40'HC | R18: 20'RE | S18: 40'RH | T18: 20'OT | U18: 40'OT | V18: 20'FR | W18: 40'FR | Y18: WK | AA18: 20'GP | AB18: 40'GP | AC18: 40'HC | AD18: 20'RE | AE18: 40'RH | AF18: 20'OT | AG18: 40'OT | AH18: 20'FR | AI18: 40'FR
B19: Stock empty in yard | C19: 0 | D19: 0 | E19: 0 | F19: 29 | G19: 35 | H19: 0 | I19: 0 | J19: 0 | K19: 0 | N19: Stock empty in yard | O19: 0 | P19: 0 | Q19: 0 | R19: 0 | S19: 0 | T19: 0 | U19: 0 | V19: 0 | W19: 0 | Z19: Stock empty in yard | AA19: 0 | AB19: 0 | AC19: 0 | AD19: 0 | AE19: 0 | AF19: 0 | AG19: 0 | AH19: 0 | AI19: 0
A20: =Control!$A$4 -> 37 | B20: Booking Pending pick up | C20: =SUMIFS(BookingRaw!$C$2:$C$600,BookingRaw!$A$2:$A$600,"BKK27",BookingRaw!$B$2:$B$600,"<"&Control!$B$1) -> 0 | D20: =SUMIFS(BookingRaw!$D$2:$D$600,BookingRaw!$A$2:$A$600,"BKK27",BookingRaw!$B$2:$B$600,"<"&Control!$B$1) -> 0 | E20: =SUMIFS(BookingRaw!$E$2:$E$600,BookingRaw!$A$2:$A$600,"BKK27",BookingRaw!$B$2:$B$600,"<"&Control!$B$1) -> 0 | F20: =SUMIFS(BookingRaw!$F$2:$F$600,BookingRaw!$A$2:$A$600,"BKK27",BookingRaw!$B$2:$B$600,"<"&Control!$B$1) -> 0 | G20: =SUMIFS(BookingRaw!$G$2:$G$600,BookingRaw!$A$2:$A$600,"BKK27",BookingRaw!$B$2:$B$600,"<"&Control!$B$1) -> 0 | H20: =SUMIFS(BookingRaw!$H$2:$H$600,BookingRaw!$A$2:$A$600,"BKK27",BookingRaw!$B$2:$B$600,"<"&Control!$B$1) -> 0 | I20: =SUMIFS(BookingRaw!$I$2:$I$600,BookingRaw!$A$2:$A$600,"BKK27",BookingRaw!$B$2:$B$600,"<"&Control!$B$1) -> 0 | J20: =SUMIFS(BookingRaw!$J$2:$J$600,BookingRaw!$A$2:$A$600,"BKK27",BookingRaw!$B$2:$B$600,"<"&Control!$B$1) -> 0 | K20: =SUMIFS(BookingRaw!$K$2:$K$600,BookingRaw!$A$2:$A$600,"BKK27",BookingRaw!$B$2:$B$600,"<"&Control!$B$1) -> 0 | M20: =Control!$A$4 -> 37 | N20: Booking Pending pick up | O20: =SUMIFS(BookingRaw!$C$2:$C$600,BookingRaw!$A$2:$A$600,"BKK02",BookingRaw!$B$2:$B$600,"<"&Control!$B$1) -> 0 | P20: =SUMIFS(BookingRaw!$D$2:$D$600,BookingRaw!$A$2:$A$600,"BKK02",BookingRaw!$B$2:$B$600,"<"&Control!$B$1) -> 0 | Q20: =SUMIFS(BookingRaw!$E$2:$E$600,BookingRaw!$A$2:$A$600,"BKK02",BookingRaw!$B$2:$B$600,"<"&Control!$B$1) -> 0 | R20: =SUMIFS(BookingRaw!$F$2:$F$600,BookingRaw!$A$2:$A$600,"BKK02",BookingRaw!$B$2:$B$600,"<"&Control!$B$1) -> 0 | S20: =SUMIFS(BookingRaw!$G$2:$G$600,BookingRaw!$A$2:$A$600,"BKK02",BookingRaw!$B$2:$B$600,"<"&Control!$B$1) -> 0 | T20: =SUMIFS(BookingRaw!$H$2:$H$600,BookingRaw!$A$2:$A$600,"BKK02",BookingRaw!$B$2:$B$600,"<"&Control!$B$1) -> 0 | U20: =SUMIFS(BookingRaw!$I$2:$I$600,BookingRaw!$A$2:$A$600,"BKK02",BookingRaw!$B$2:$B$600,"<"&Control!$B$1) -> 0 | V20: =SUMIFS(BookingRaw!$J$2:$J$600,BookingRaw!$A$2:$A$600,"BKK02",BookingRaw!$B$2:$B$600,"<"&Control!$B$1) -> 0 | W20: =SUMIFS(BookingRaw!$K$2:$K$600,BookingRaw!$A$2:$A$600,"BKK02",BookingRaw!$B$2:$B$600,"<"&Control!$B$1) -> 0 | Y20: =Control!$A$4 -> 37 | Z20: Booking Pending pick up | AA20: =SUMIFS(BookingRaw!$C$2:$C$600,BookingRaw!$A$2:$A$600,"LCH28",BookingRaw!$B$2:$B$600,"<"&Control!$B$1) -> 0 | AB20: =SUMIFS(BookingRaw!$D$2:$D$600,BookingRaw!$A$2:$A$600,"LCH28",BookingRaw!$B$2:$B$600,"<"&Control!$B$1) -> 0 | AC20: =SUMIFS(BookingRaw!$E$2:$E$600,BookingRaw!$A$2:$A$600,"LCH28",BookingRaw!$B$2:$B$600,"<"&Control!$B$1) -> 0 | AD20: =SUMIFS(BookingRaw!$F$2:$F$600,BookingRaw!$A$2:$A$600,"LCH28",BookingRaw!$B$2:$B$600,"<"&Control!$B$1) -> 0 | AE20: =SUMIFS(BookingRaw!$G$2:$G$600,BookingRaw!$A$2:$A$600,"LCH28",BookingRaw!$B$2:$B$600,"<"&Control!$B$1) -> 0 | AF20: =SUMIFS(BookingRaw!$H$2:$H$600,BookingRaw!$A$2:$A$600,"LCH28",BookingRaw!$B$2:$B$600,"<"&Control!$B$1) -> 0 | AG20: =SUMIFS(BookingRaw!$I$2:$I$600,BookingRaw!$A$2:$A$600,"LCH28",BookingRaw!$B$2:$B$600,"<"&Control!$B$1) -> 0 | AH20: =SUMIFS(BookingRaw!$J$2:$J$600,BookingRaw!$A$2:$A$600,"LCH28",BookingRaw!$B$2:$B$600,"<"&Control!$B$1) -> 0 | AI20: =SUMIFS(BookingRaw!$K$2:$K$600,BookingRaw!$A$2:$A$600,"LCH28",BookingRaw!$B$2:$B$600,"<"&Control!$B$1) -> 0
A21: =Control!$A$4 -> 37 | B21: ="Booking on "&DAY(Control!$B$1)&" "&CHOOSE(MONTH(Control!$B$1),"Jan","Feb","Mar","Apr","May","Jun","Jul","Aug","Sep","Oct","Nov","Dec") -> Booking on 10 Sep | C21: =SUMIFS(BookingRaw!$C$2:$C$600,BookingRaw!$A$2:$A$600,"BKK27",BookingRaw!$B$2:$B$600,"="&Control!$B$1) -> 0 | D21: =SUMIFS(BookingRaw!$D$2:$D$600,BookingRaw!$A$2:$A$600,"BKK27",BookingRaw!$B$2:$B$600,"="&Control!$B$1) -> 0 | E21: =SUMIFS(BookingRaw!$E$2:$E$600,BookingRaw!$A$2:$A$600,"BKK27",BookingRaw!$B$2:$B$600,"="&Control!$B$1) -> 0 | F21: =SUMIFS(BookingRaw!$F$2:$F$600,BookingRaw!$A$2:$A$600,"BKK27",BookingRaw!$B$2:$B$600,"="&Control!$B$1) -> 0 | G21: =SUMIFS(BookingRaw!$G$2:$G$600,BookingRaw!$A$2:$A$600,"BKK27",BookingRaw!$B$2:$B$600,"="&Control!$B$1) -> 1 | H21: =SUMIFS(BookingRaw!$H$2:$H$600,BookingRaw!$A$2:$A$600,"BKK27",BookingRaw!$B$2:$B$600,"="&Control!$B$1) -> 0 | I21: =SUMIFS(BookingRaw!$I$2:$I$600,BookingRaw!$A$2:$A$600,"BKK27",BookingRaw!$B$2:$B$600,"="&Control!$B$1) -> 0 | J21: =SUMIFS(BookingRaw!$J$2:$J$600,BookingRaw!$A$2:$A$600,"BKK27",BookingRaw!$B$2:$B$600,"="&Control!$B$1) -> 0 | K21: =SUMIFS(BookingRaw!$K$2:$K$600,BookingRaw!$A$2:$A$600,"BKK27",BookingRaw!$B$2:$B$600,"="&Control!$B$1) -> 0 | M21: =Control!$A$4 -> 37 | N21: ="Booking on "&DAY(Control!$B$1)&" "&CHOOSE(MONTH(Control!$B$1),"Jan","Feb","Mar","Apr","May","Jun","Jul","Aug","Sep","Oct","Nov","Dec") -> Booking on 10 Sep | O21: =SUMIFS(BookingRaw!$C$2:$C$600,BookingRaw!$A$2:$A$600,"BKK02",BookingRaw!$B$2:$B$600,"="&Control!$B$1) -> 0 | P21: =SUMIFS(BookingRaw!$D$2:$D$600,BookingRaw!$A$2:$A$600,"BKK02",BookingRaw!$B$2:$B$600,"="&Control!$B$1) -> 0 | Q21: =SUMIFS(BookingRaw!$E$2:$E$600,BookingRaw!$A$2:$A$600,"BKK02",BookingRaw!$B$2:$B$600,"="&Control!$B$1) -> 0 | R21: =SUMIFS(BookingRaw!$F$2:$F$600,BookingRaw!$A$2:$A$600,"BKK02",BookingRaw!$B$2:$B$600,"="&Control!$B$1) -> 0 | S21: =SUMIFS(BookingRaw!$G$2:$G$600,BookingRaw!$A$2:$A$600,"BKK02",BookingRaw!$B$2:$B$600,"="&Control!$B$1) -> 0 | T21: =SUMIFS(BookingRaw!$H$2:$H$600,BookingRaw!$A$2:$A$600,"BKK02",BookingRaw!$B$2:$B$600,"="&Control!$B$1) -> 0 | U21: =SUMIFS(BookingRaw!$I$2:$I$600,BookingRaw!$A$2:$A$600,"BKK02",BookingRaw!$B$2:$B$600,"="&Control!$B$1) -> 0 | V21: =SUMIFS(BookingRaw!$J$2:$J$600,BookingRaw!$A$2:$A$600,"BKK02",BookingRaw!$B$2:$B$600,"="&Control!$B$1) -> 0 | W21: =SUMIFS(BookingRaw!$K$2:$K$600,BookingRaw!$A$2:$A$600,"BKK02",BookingRaw!$B$2:$B$600,"="&Control!$B$1) -> 0 | Y21: =Control!$A$4 -> 37 | Z21: ="Booking on "&DAY(Control!$B$1)&" "&CHOOSE(MONTH(Control!$B$1),"Jan","Feb","Mar","Apr","May","Jun","Jul","Aug","Sep","Oct","Nov","Dec") -> Booking on 10 Sep | AA21: =SUMIFS(BookingRaw!$C$2:$C$600,BookingRaw!$A$2:$A$600,"LCH28",BookingRaw!$B$2:$B$600,"="&Control!$B$1) -> 0 | AB21: =SUMIFS(BookingRaw!$D$2:$D$600,BookingRaw!$A$2:$A$600,"LCH28",BookingRaw!$B$2:$B$600,"="&Control!$B$1) -> 0 | AC21: =SUMIFS(BookingRaw!$E$2:$E$600,BookingRaw!$A$2:$A$600,"LCH28",BookingRaw!$B$2:$B$600,"="&Control!$B$1) -> 0 | AD21: =SUMIFS(BookingRaw!$F$2:$F$600,BookingRaw!$A$2:$A$600,"LCH28",BookingRaw!$B$2:$B$600,"="&Control!$B$1) -> 0 | AE21: =SUMIFS(BookingRaw!$G$2:$G$600,BookingRaw!$A$2:$A$600,"LCH28",BookingRaw!$B$2:$B$600,"="&Control!$B$1) -> 0 | AF21: =SUMIFS(BookingRaw!$H$2:$H$600,BookingRaw!$A$2:$A$600,"LCH28",BookingRaw!$B$2:$B$600,"="&Control!$B$1) -> 0 | AG21: =SUMIFS(BookingRaw!$I$2:$I$600,BookingRaw!$A$2:$A$600,"LCH28",BookingRaw!$B$2:$B$600,"="&Control!$B$1) -> 0 | AH21: =SUMIFS(BookingRaw!$J$2:$J$600,BookingRaw!$A$2:$A$600,"LCH28",BookingRaw!$B$2:$B$600,"="&Control!$B$1) -> 0 | AI21: =SUMIFS(BookingRaw!$K$2:$K$600,BookingRaw!$A$2:$A$600,"LCH28",BookingRaw!$B$2:$B$600,"="&Control!$B$1) -> 0
A22: =Control!$A$4 -> 37 | B22: =IF(Control!$B$9=Control!$C$4,DAY(Control!$B$9)&" "&CHOOSE(MONTH(Control!$B$9),"Jan","Feb","Mar","Apr","May","Jun","Jul","Aug","Sep","Oct","Nov","Dec"),"Booking on "&IF(MONTH(Control!$B$9)=MONTH(Control!$C$4),DAY(Control!$B$9)&"-"&DAY(Control!$C$4)&" "&CHOOSE(MONTH(Control!$C$4),"Jan","Feb","Mar","Apr","May","Jun","Jul","Aug","Sep","Oct","Nov","Dec"),DAY(Control!$B$9)&" "&CHOOSE(MONTH(Control!$B$9),"Jan","Feb","Mar","Apr","May","Jun","Jul","Aug","Sep","Oct","Nov","Dec")&"-"&DAY(Control!$C$4)&" "&CHOOSE(MONTH(Control!$C$4),"Jan","Feb","Mar","Apr","May","Jun","Jul","Aug","Sep","Oct","Nov","Dec"))) -> Booking on 11-12 Sep | C22: =SUMIFS(BookingRaw!$C$2:$C$600,BookingRaw!$A$2:$A$600,"BKK27",BookingRaw!$B$2:$B$600,">="&Control!$B$9,BookingRaw!$B$2:$B$600,"<="&Control!$C$4) -> 0 | D22: =SUMIFS(BookingRaw!$D$2:$D$600,BookingRaw!$A$2:$A$600,"BKK27",BookingRaw!$B$2:$B$600,">="&Control!$B$9,BookingRaw!$B$2:$B$600,"<="&Control!$C$4) -> 0 | E22: =SUMIFS(BookingRaw!$E$2:$E$600,BookingRaw!$A$2:$A$600,"BKK27",BookingRaw!$B$2:$B$600,">="&Control!$B$9,BookingRaw!$B$2:$B$600,"<="&Control!$C$4) -> 0 | F22: =SUMIFS(BookingRaw!$F$2:$F$600,BookingRaw!$A$2:$A$600,"BKK27",BookingRaw!$B$2:$B$600,">="&Control!$B$9,BookingRaw!$B$2:$B$600,"<="&Control!$C$4) -> 0 | G22: =SUMIFS(BookingRaw!$G$2:$G$600,BookingRaw!$A$2:$A$600,"BKK27",BookingRaw!$B$2:$B$600,">="&Control!$B$9,BookingRaw!$B$2:$B$600,"<="&Control!$C$4) -> 5 | H22: =SUMIFS(BookingRaw!$H$2:$H$600,BookingRaw!$A$2:$A$600,"BKK27",BookingRaw!$B$2:$B$600,">="&Control!$B$9,BookingRaw!$B$2:$B$600,"<="&Control!$C$4) -> 0 | I22: =SUMIFS(BookingRaw!$I$2:$I$600,BookingRaw!$A$2:$A$600,"BKK27",BookingRaw!$B$2:$B$600,">="&Control!$B$9,BookingRaw!$B$2:$B$600,"<="&Control!$C$4) -> 0 | J22: =SUMIFS(BookingRaw!$J$2:$J$600,BookingRaw!$A$2:$A$600,"BKK27",BookingRaw!$B$2:$B$600,">="&Control!$B$9,BookingRaw!$B$2:$B$600,"<="&Control!$C$4) -> 0 | K22: =SUMIFS(BookingRaw!$K$2:$K$600,BookingRaw!$A$2:$A$600,"BKK27",BookingRaw!$B$2:$B$600,">="&Control!$B$9,BookingRaw!$B$2:$B$600,"<="&Control!$C$4) -> 0 | M22: =Control!$A$4 -> 37 | N22: =IF(Control!$B$9=Control!$C$4,DAY(Control!$B$9)&" "&CHOOSE(MONTH(Control!$B$9),"Jan","Feb","Mar","Apr","May","Jun","Jul","Aug","Sep","Oct","Nov","Dec"),"Booking on "&IF(MONTH(Control!$B$9)=MONTH(Control!$C$4),DAY(Control!$B$9)&"-"&DAY(Control!$C$4)&" "&CHOOSE(MONTH(Control!$C$4),"Jan","Feb","Mar","Apr","May","Jun","Jul","Aug","Sep","Oct","Nov","Dec"),DAY(Control!$B$9)&" "&CHOOSE(MONTH(Control!$B$9),"Jan","Feb","Mar","Apr","May","Jun","Jul","Aug","Sep","Oct","Nov","Dec")&"-"&DAY(Control!$C$4)&" "&CHOOSE(MONTH(Control!$C$4),"Jan","Feb","Mar","Apr","May","Jun","Jul","Aug","Sep","Oct","Nov","Dec"))) -> Booking on 11-12 Sep | O22: =SUMIFS(BookingRaw!$C$2:$C$600,BookingRaw!$A$2:$A$600,"BKK02",BookingRaw!$B$2:$B$600,">="&Control!$B$9,BookingRaw!$B$2:$B$600,"<="&Control!$C$4) -> 0 | P22: =SUMIFS(BookingRaw!$D$2:$D$600,BookingRaw!$A$2:$A$600,"BKK02",BookingRaw!$B$2:$B$600,">="&Control!$B$9,BookingRaw!$B$2:$B$600,"<="&Control!$C$4) -> 0 | Q22: =SUMIFS(BookingRaw!$E$2:$E$600,BookingRaw!$A$2:$A$600,"BKK02",BookingRaw!$B$2:$B$600,">="&Control!$B$9,BookingRaw!$B$2:$B$600,"<="&Control!$C$4) -> 0 | R22: =SUMIFS(BookingRaw!$F$2:$F$600,BookingRaw!$A$2:$A$600,"BKK02",BookingRaw!$B$2:$B$600,">="&Control!$B$9,BookingRaw!$B$2:$B$600,"<="&Control!$C$4) -> 0 | S22: =SUMIFS(BookingRaw!$G$2:$G$600,BookingRaw!$A$2:$A$600,"BKK02",BookingRaw!$B$2:$B$600,">="&Control!$B$9,BookingRaw!$B$2:$B$600,"<="&Control!$C$4) -> 0 | T22: =SUMIFS(BookingRaw!$H$2:$H$600,BookingRaw!$A$2:$A$600,"BKK02",BookingRaw!$B$2:$B$600,">="&Control!$B$9,BookingRaw!$B$2:$B$600,"<="&Control!$C$4) -> 0 | U22: =SUMIFS(BookingRaw!$I$2:$I$600,BookingRaw!$A$2:$A$600,"BKK02",BookingRaw!$B$2:$B$600,">="&Control!$B$9,BookingRaw!$B$2:$B$600,"<="&Control!$C$4) -> 0 | V22: =SUMIFS(BookingRaw!$J$2:$J$600,BookingRaw!$A$2:$A$600,"BKK02",BookingRaw!$B$2:$B$600,">="&Control!$B$9,BookingRaw!$B$2:$B$600,"<="&Control!$C$4) -> 0 | W22: =SUMIFS(BookingRaw!$K$2:$K$600,BookingRaw!$A$2:$A$600,"BKK02",BookingRaw!$B$2:$B$600,">="&Control!$B$9,BookingRaw!$B$2:$B$600,"<="&Control!$C$4) -> 0 | Y22: =Control!$A$4 -> 37 | Z22: =IF(Control!$B$9=Control!$C$4,DAY(Control!$B$9)&" "&CHOOSE(MONTH(Control!$B$9),"Jan","Feb","Mar","Apr","May","Jun","Jul","Aug","Sep","Oct","Nov","Dec"),"Booking on "&IF(MONTH(Control!$B$9)=MONTH(Control!$C$4),DAY(Control!$B$9)&"-"&DAY(Control!$C$4)&" "&CHOOSE(MONTH(Control!$C$4),"Jan","Feb","Mar","Apr","May","Jun","Jul","Aug","Sep","Oct","Nov","Dec"),DAY(Control!$B$9)&" "&CHOOSE(MONTH(Control!$B$9),"Jan","Feb","Mar","Apr","May","Jun","Jul","Aug","Sep","Oct","Nov","Dec")&"-"&DAY(Control!$C$4)&" "&CHOOSE(MONTH(Control!$C$4),"Jan","Feb","Mar","Apr","May","Jun","Jul","Aug","Sep","Oct","Nov","Dec"))) -> Booking on 11-12 Sep | AA22: =SUMIFS(BookingRaw!$C$2:$C$600,BookingRaw!$A$2:$A$600,"LCH28",BookingRaw!$B$2:$B$600,">="&Control!$B$9,BookingRaw!$B$2:$B$600,"<="&Control!$C$4) -> 0 | AB22: =SUMIFS(BookingRaw!$D$2:$D$600,BookingRaw!$A$2:$A$600,"LCH28",BookingRaw!$B$2:$B$600,">="&Control!$B$9,BookingRaw!$B$2:$B$600,"<="&Control!$C$4) -> 0 | AC22: =SUMIFS(BookingRaw!$E$2:$E$600,BookingRaw!$A$2:$A$600,"LCH28",BookingRaw!$B$2:$B$600,">="&Control!$B$9,BookingRaw!$B$2:$B$600,"<="&Control!$C$4) -> 0 | AD22: =SUMIFS(BookingRaw!$F$2:$F$600,BookingRaw!$A$2:$A$600,"LCH28",BookingRaw!$B$2:$B$600,">="&Control!$B$9,BookingRaw!$B$2:$B$600,"<="&Control!$C$4) -> 0 | AE22: =SUMIFS(BookingRaw!$G$2:$G$600,BookingRaw!$A$2:$A$600,"LCH28",BookingRaw!$B$2:$B$600,">="&Control!$B$9,BookingRaw!$B$2:$B$600,"<="&Control!$C$4) -> 0 | AF22: =SUMIFS(BookingRaw!$H$2:$H$600,BookingRaw!$A$2:$A$600,"LCH28",BookingRaw!$B$2:$B$600,">="&Control!$B$9,BookingRaw!$B$2:$B$600,"<="&Control!$C$4) -> 0 | AG22: =SUMIFS(BookingRaw!$I$2:$I$600,BookingRaw!$A$2:$A$600,"LCH28",BookingRaw!$B$2:$B$600,">="&Control!$B$9,BookingRaw!$B$2:$B$600,"<="&Control!$C$4) -> 0 | AH22: =SUMIFS(BookingRaw!$J$2:$J$600,BookingRaw!$A$2:$A$600,"LCH28",BookingRaw!$B$2:$B$600,">="&Control!$B$9,BookingRaw!$B$2:$B$600,"<="&Control!$C$4) -> 0 | AI22: =SUMIFS(BookingRaw!$K$2:$K$600,BookingRaw!$A$2:$A$600,"LCH28",BookingRaw!$B$2:$B$600,">="&Control!$B$9,BookingRaw!$B$2:$B$600,"<="&Control!$C$4) -> 0
B23: ="AV Balance till "&DAY(Control!$C$4)&" "&CHOOSE(MONTH(Control!$C$4),"Jan","Feb","Mar","Apr","May","Jun","Jul","Aug","Sep","Oct","Nov","Dec") -> AV Balance till 12 Sep | C23: =C19-C20-C21-C22 -> 0 | D23: =D19-D20-D21-D22 -> 0 | E23: =E19-E20-E21-E22 -> 0 | F23: =F19-F20-F21-F22 -> 29 | G23: =G19-G20-G21-G22 -> 29 | H23: =H19-H20-H21-H22 -> 0 | I23: =I19-I20-I21-I22 -> 0 | J23: =J19-J20-J21-J22 -> 0 | K23: =K19-K20-K21-K22 -> 0 | N23: ="AV Balance till "&DAY(Control!$C$4)&" "&CHOOSE(MONTH(Control!$C$4),"Jan","Feb","Mar","Apr","May","Jun","Jul","Aug","Sep","Oct","Nov","Dec") -> AV Balance till 12 Sep | O23: =O19-O20-O21-O22 -> 0 | P23: =P19-P20-P21-P22 -> 0 | Q23: =Q19-Q20-Q21-Q22 -> 0 | R23: =R19-R20-R21-R22 -> 0 | S23: =S19-S20-S21-S22 -> 0 | T23: =T19-T20-T21-T22 -> 0 | U23: =U19-U20-U21-U22 -> 0 | V23: =V19-V20-V21-V22 -> 0 | W23: =W19-W20-W21-W22 -> 0 | Z23: ="AV Balance till "&DAY(Control!$C$4)&" "&CHOOSE(MONTH(Control!$C$4),"Jan","Feb","Mar","Apr","May","Jun","Jul","Aug","Sep","Oct","Nov","Dec") -> AV Balance till 12 Sep | AA23: =AA19-AA20-AA21-AA22 -> 0 | AB23: =AB19-AB20-AB21-AB22 -> 0 | AC23: =AC19-AC20-AC21-AC22 -> 0 | AD23: =AD19-AD20-AD21-AD22 -> 0 | AE23: =AE19-AE20-AE21-AE22 -> 0 | AF23: =AF19-AF20-AF21-AF22 -> 0 | AG23: =AG19-AG20-AG21-AG22 -> 0 | AH23: =AH19-AH20-AH21-AH22 -> 0 | AI23: =AI19-AI20-AI21-AI22 -> 0
A24: =Control!$A$5 -> 38 | B24: ="Booking on "&IF(MONTH(Control!$B$5)=MONTH(Control!$C$5),DAY(Control!$B$5)&"-"&DAY(Control!$C$5)&" "&CHOOSE(MONTH(Control!$C$5),"Jan","Feb","Mar","Apr","May","Jun","Jul","Aug","Sep","Oct","Nov","Dec"),DAY(Control!$B$5)&" "&CHOOSE(MONTH(Control!$B$5),"Jan","Feb","Mar","Apr","May","Jun","Jul","Aug","Sep","Oct","Nov","Dec")&"-"&DAY(Control!$C$5)&" "&CHOOSE(MONTH(Control!$C$5),"Jan","Feb","Mar","Apr","May","Jun","Jul","Aug","Sep","Oct","Nov","Dec")) -> Booking on 14-19 Sep | C24: =SUMIFS(BookingRaw!$C$2:$C$600,BookingRaw!$A$2:$A$600,"BKK27",BookingRaw!$B$2:$B$600,">="&Control!$B$5,BookingRaw!$B$2:$B$600,"<="&Control!$C$5) -> 0 | D24: =SUMIFS(BookingRaw!$D$2:$D$600,BookingRaw!$A$2:$A$600,"BKK27",BookingRaw!$B$2:$B$600,">="&Control!$B$5,BookingRaw!$B$2:$B$600,"<="&Control!$C$5) -> 0 | E24: =SUMIFS(BookingRaw!$E$2:$E$600,BookingRaw!$A$2:$A$600,"BKK27",BookingRaw!$B$2:$B$600,">="&Control!$B$5,BookingRaw!$B$2:$B$600,"<="&Control!$C$5) -> 0 | F24: =SUMIFS(BookingRaw!$F$2:$F$600,BookingRaw!$A$2:$A$600,"BKK27",BookingRaw!$B$2:$B$600,">="&Control!$B$5,BookingRaw!$B$2:$B$600,"<="&Control!$C$5) -> 11 | G24: =SUMIFS(BookingRaw!$G$2:$G$600,BookingRaw!$A$2:$A$600,"BKK27",BookingRaw!$B$2:$B$600,">="&Control!$B$5,BookingRaw!$B$2:$B$600,"<="&Control!$C$5) -> 37 | H24: =SUMIFS(BookingRaw!$H$2:$H$600,BookingRaw!$A$2:$A$600,"BKK27",BookingRaw!$B$2:$B$600,">="&Control!$B$5,BookingRaw!$B$2:$B$600,"<="&Control!$C$5) -> 0 | I24: =SUMIFS(BookingRaw!$I$2:$I$600,BookingRaw!$A$2:$A$600,"BKK27",BookingRaw!$B$2:$B$600,">="&Control!$B$5,BookingRaw!$B$2:$B$600,"<="&Control!$C$5) -> 0 | J24: =SUMIFS(BookingRaw!$J$2:$J$600,BookingRaw!$A$2:$A$600,"BKK27",BookingRaw!$B$2:$B$600,">="&Control!$B$5,BookingRaw!$B$2:$B$600,"<="&Control!$C$5) -> 0 | K24: =SUMIFS(BookingRaw!$K$2:$K$600,BookingRaw!$A$2:$A$600,"BKK27",BookingRaw!$B$2:$B$600,">="&Control!$B$5,BookingRaw!$B$2:$B$600,"<="&Control!$C$5) -> 0 | M24: =Control!$A$5 -> 38 | N24: ="Booking on "&IF(MONTH(Control!$B$5)=MONTH(Control!$C$5),DAY(Control!$B$5)&"-"&DAY(Control!$C$5)&" "&CHOOSE(MONTH(Control!$C$5),"Jan","Feb","Mar","Apr","May","Jun","Jul","Aug","Sep","Oct","Nov","Dec"),DAY(Control!$B$5)&" "&CHOOSE(MONTH(Control!$B$5),"Jan","Feb","Mar","Apr","May","Jun","Jul","Aug","Sep","Oct","Nov","Dec")&"-"&DAY(Control!$C$5)&" "&CHOOSE(MONTH(Control!$C$5),"Jan","Feb","Mar","Apr","May","Jun","Jul","Aug","Sep","Oct","Nov","Dec")) -> Booking on 14-19 Sep | O24: =SUMIFS(BookingRaw!$C$2:$C$600,BookingRaw!$A$2:$A$600,"BKK02",BookingRaw!$B$2:$B$600,">="&Control!$B$5,BookingRaw!$B$2:$B$600,"<="&Control!$C$5) -> 0 | P24: =SUMIFS(BookingRaw!$D$2:$D$600,BookingRaw!$A$2:$A$600,"BKK02",BookingRaw!$B$2:$B$600,">="&Control!$B$5,BookingRaw!$B$2:$B$600,"<="&Control!$C$5) -> 0 | Q24: =SUMIFS(BookingRaw!$E$2:$E$600,BookingRaw!$A$2:$A$600,"BKK02",BookingRaw!$B$2:$B$600,">="&Control!$B$5,BookingRaw!$B$2:$B$600,"<="&Control!$C$5) -> 0 | R24: =SUMIFS(BookingRaw!$F$2:$F$600,BookingRaw!$A$2:$A$600,"BKK02",BookingRaw!$B$2:$B$600,">="&Control!$B$5,BookingRaw!$B$2:$B$600,"<="&Control!$C$5) -> 0 | S24: =SUMIFS(BookingRaw!$G$2:$G$600,BookingRaw!$A$2:$A$600,"BKK02",BookingRaw!$B$2:$B$600,">="&Control!$B$5,BookingRaw!$B$2:$B$600,"<="&Control!$C$5) -> 0 | T24: =SUMIFS(BookingRaw!$H$2:$H$600,BookingRaw!$A$2:$A$600,"BKK02",BookingRaw!$B$2:$B$600,">="&Control!$B$5,BookingRaw!$B$2:$B$600,"<="&Control!$C$5) -> 0 | U24: =SUMIFS(BookingRaw!$I$2:$I$600,BookingRaw!$A$2:$A$600,"BKK02",BookingRaw!$B$2:$B$600,">="&Control!$B$5,BookingRaw!$B$2:$B$600,"<="&Control!$C$5) -> 0 | V24: =SUMIFS(BookingRaw!$J$2:$J$600,BookingRaw!$A$2:$A$600,"BKK02",BookingRaw!$B$2:$B$600,">="&Control!$B$5,BookingRaw!$B$2:$B$600,"<="&Control!$C$5) -> 0 | W24: =SUMIFS(BookingRaw!$K$2:$K$600,BookingRaw!$A$2:$A$600,"BKK02",BookingRaw!$B$2:$B$600,">="&Control!$B$5,BookingRaw!$B$2:$B$600,"<="&Control!$C$5) -> 0 | Y24: =Control!$A$5 -> 38 | Z24: ="Booking on "&IF(MONTH(Control!$B$5)=MONTH(Control!$C$5),DAY(Control!$B$5)&"-"&DAY(Control!$C$5)&" "&CHOOSE(MONTH(Control!$C$5),"Jan","Feb","Mar","Apr","May","Jun","Jul","Aug","Sep","Oct","Nov","Dec"),DAY(Control!$B$5)&" "&CHOOSE(MONTH(Control!$B$5),"Jan","Feb","Mar","Apr","May","Jun","Jul","Aug","Sep","Oct","Nov","Dec")&"-"&DAY(Control!$C$5)&" "&CHOOSE(MONTH(Control!$C$5),"Jan","Feb","Mar","Apr","May","Jun","Jul","Aug","Sep","Oct","Nov","Dec")) -> Booking on 14-19 Sep | AA24: =SUMIFS(BookingRaw!$C$2:$C$600,BookingRaw!$A$2:$A$600,"LCH28",BookingRaw!$B$2:$B$600,">="&Control!$B$5,BookingRaw!$B$2:$B$600,"<="&Control!$C$5) -> 0 | AB24: =SUMIFS(BookingRaw!$D$2:$D$600,BookingRaw!$A$2:$A$600,"LCH28",BookingRaw!$B$2:$B$600,">="&Control!$B$5,BookingRaw!$B$2:$B$600,"<="&Control!$C$5) -> 0 | AC24: =SUMIFS(BookingRaw!$E$2:$E$600,BookingRaw!$A$2:$A$600,"LCH28",BookingRaw!$B$2:$B$600,">="&Control!$B$5,BookingRaw!$B$2:$B$600,"<="&Control!$C$5) -> 0 | AD24: =SUMIFS(BookingRaw!$F$2:$F$600,BookingRaw!$A$2:$A$600,"LCH28",BookingRaw!$B$2:$B$600,">="&Control!$B$5,BookingRaw!$B$2:$B$600,"<="&Control!$C$5) -> 0 | AE24: =SUMIFS(BookingRaw!$G$2:$G$600,BookingRaw!$A$2:$A$600,"LCH28",BookingRaw!$B$2:$B$600,">="&Control!$B$5,BookingRaw!$B$2:$B$600,"<="&Control!$C$5) -> 0 | AF24: =SUMIFS(BookingRaw!$H$2:$H$600,BookingRaw!$A$2:$A$600,"LCH28",BookingRaw!$B$2:$B$600,">="&Control!$B$5,BookingRaw!$B$2:$B$600,"<="&Control!$C$5) -> 0 | AG24: =SUMIFS(BookingRaw!$I$2:$I$600,BookingRaw!$A$2:$A$600,"LCH28",BookingRaw!$B$2:$B$600,">="&Control!$B$5,BookingRaw!$B$2:$B$600,"<="&Control!$C$5) -> 0 | AH24: =SUMIFS(BookingRaw!$J$2:$J$600,BookingRaw!$A$2:$A$600,"LCH28",BookingRaw!$B$2:$B$600,">="&Control!$B$5,BookingRaw!$B$2:$B$600,"<="&Control!$C$5) -> 0 | AI24: =SUMIFS(BookingRaw!$K$2:$K$600,BookingRaw!$A$2:$A$600,"LCH28",BookingRaw!$B$2:$B$600,">="&Control!$B$5,BookingRaw!$B$2:$B$600,"<="&Control!$C$5) -> 0
