Workbook

Sheet Control
A1: Report date | B1: 46281
A3: WK# | B3: Monday | C3: Saturday
A4: =WEEKNUM(B4,21) -> 38 | B4: =$B$1-(WEEKDAY($B$1,2)-1) -> 46279 | C4: =B4+5 -> 46284
A5: =WEEKNUM(B5,21) -> 39 | B5: =B4+7 -> 46286 | C5: =B5+5 -> 46291
A6: =WEEKNUM(B6,21) -> 40 | B6: =B5+7 -> 46293 | C6: =B6+5 -> 46298
A7: =WEEKNUM(B7,21) -> 41 | B7: =B6+7 -> 46300 | C7: =B7+5 -> 46305
A9: Tomorrow | B9: =B1+1 -> 46282

Sheet BookingRaw
A1: Location | B1: Pickup Date | C1: 20'RE | D1: 40'RH
A2: LCH27 | B2: 46286 | C2: 1 | D2: 0
A3: BKK27 | B3: 46283 | C3: 1 | D3: 0
A4: BKK27 | B4: 46281 | C4: 1 | D4: 0
A5: BKK27 | B5: 46294 | C5: 1 | D5: 0
A6: BKK27 | B6: 46287 | C6: 1 | D6: 0
A7: BKK27 | B7: 46289 | C7: 1 | D7: 0
A8: BKK27 | B8: 46282 | C8: 1 | D8: 0
A9: LCH27 | B9: 46286 | C9: 1 | D9: 0
A10: BKK27 | B10: 46294 | C10: 1 | D10: 0
A11: BKK27 | B11: 46283 | C11: 1 | D11: 0
A12: BKK27 | B12: 46283 | C12: 1 | D12: 0
A13: BKK27 | B13: 46283 | C13: 1 | D13: 0
... A109: BKK27 | B109: 46279 | C109: 0 | D109: 3

Sheet TOTAL RH
A1: ="Stock vs Booking Report - Reefer (20'RE / 40'RH) as of "&DAY(Control!$B$1)&" "&CHOOSE(MONTH(Control!$B$1),"JAN","FEB","MAR","APR","MAY","JUN","JUL","AUG","SEP","OCT","NOV","DEC")&" "&YEAR(Control!$B$1) -> Stock vs Booking Report - Reefer (20'RE / 40'RH) as of 16 SEP 2026
B2: BKK27 / BC2 | H2: LCH27 / HAST | M2: STOCK | N2: 22RE | O2: 45RE
A3: WK | C3: 20'RE | D3: 40'RH | G3: WK | I3: 20'RE | J3: 40'RH | M3: BC | N3: =C4 -> 31 | O3: =D4 -> 50
B4: Stock empty in yard | C4: 31 | D4: 50 | H4: Stock empty in yard | I4: 8 | J4: 63 | M4: HAST | N4: =I4 -> 8 | O4: =J4 -> 63
A5: =Control!$A$4 -> 38 | B5: Booking Pending pick up | C5: =SUMIFS(BookingRaw!$C$2:$C$8000,BookingRaw!$A$2:$A$8000,"BKK27",BookingRaw!$B$2:$B$8000,"<"&Control!$B$1) -> 0 | D5: =SUMIFS(BookingRaw!$D$2:$D$8000,BookingRaw!$A$2:$A$8000,"BKK27",BookingRaw!$B$2:$B$8000,"<"&Control!$B$1) -> 8 | G5: =Control!$A$4 -> 38 | H5: Booking Pending pick up | I5: =SUMIFS(BookingRaw!$C$2:$C$8000,BookingRaw!$A$2:$A$8000,"LCH27",BookingRaw!$B$2:$B$8000,"<"&Control!$B$1) -> 0 | J5: =SUMIFS(BookingRaw!$D$2:$D$8000,BookingRaw!$A$2:$A$8000,"LCH27",BookingRaw!$B$2:$B$8000,"<"&Control!$B$1) -> 13 | M5: TOTAL | N5: =SUM(N3:N4) -> 39 | O5: =SUM(O3:O4) -> 113
A6: =Control!$A$4 -> 38 | B6: ="Booking on "&DAY(Control!$B$1)&" "&CHOOSE(MONTH(Control!$B$1),"JAN","FEB","MAR","APR","MAY","JUN","JUL","AUG","SEP","OCT","NOV","DEC") -> Booking on 16 SEP | C6: =SUMIFS(BookingRaw!$C$2:$C$8000,BookingRaw!$A$2:$A$8000,"BKK27",BookingRaw!$B$2:$B$8000,"="&Control!$B$1) -> 2 | D6: =SUMIFS(BookingRaw!$D$2:$D$8000,BookingRaw!$A$2:$A$8000,"BKK27",BookingRaw!$B$2:$B$8000,"="&Control!$B$1) -> 6 | G6: =Control!$A$4 -> 38 | H6: ="Booking on "&DAY(Control!$B$1)&" "&CHOOSE(MONTH(Control!$B$1),"JAN","FEB","MAR","APR","MAY","JUN","JUL","AUG","SEP","OCT","NOV","DEC") -> Booking on 16 SEP | I6: =SUMIFS(BookingRaw!$C$2:$C$8000,BookingRaw!$A$2:$A$8000,"LCH27",BookingRaw!$B$2:$B$8000,"="&Control!$B$1) -> 0 | J6: =SUMIFS(BookingRaw!$D$2:$D$8000,BookingRaw!$A$2:$A$8000,"LCH27",BookingRaw!$B$2:$B$8000,"="&Control!$B$1) -> 8
A7: =Control!$A$4 -> 38 | B7: ="Booking on "&IF(Control!$B$9=Control!$C$4,DAY(Control!$B$9)&" "&CHOOSE(MONTH(Control!$B$9),"JAN","FEB","MAR","APR","MAY","JUN","JUL","AUG","SEP","OCT","NOV","DEC"),IF(MONTH(Control!$B$9)=MONTH(Control!$C$4),DAY(Control!$B$9)&"-"&DAY(Control!$C$4)&" "&CHOOSE(MONTH(Control!$C$4),"JAN","FEB","MAR","APR","MAY","JUN","JUL","AUG","SEP","OCT","NOV","DEC"),DAY(Control!$B$9)&" "&CHOOSE(MONTH(Control!$B$9),"JAN","FEB","MAR","APR","MAY","JUN","JUL","AUG","SEP","OCT","NOV","DEC")&"-"&DAY(Control!$C$4)&" "&CHOOSE(MONTH(Control!$C$4),"JAN","FEB","MAR","APR","MAY","JUN","JUL","AUG","SEP","OCT","NOV","DEC"))) -> Booking on 17-19 SEP | C7: =SUMIFS(BookingRaw!$C$2:$C$8000,BookingRaw!$A$2:$A$8000,"BKK27",BookingRaw!$B$2:$B$8000,">="&Control!$B$9,BookingRaw!$B$2:$B$8000,"<="&Control!$C$4) -> 6 | D7: =SUMIFS(BookingRaw!$D$2:$D$8000,BookingRaw!$A$2:$A$8000,"BKK27",BookingRaw!$B$2:$B$8000,">="&Control!$B$9,BookingRaw!$B$2:$B$8000,"<="&Control!$C$4) -> 19 | G7: =Control!$A$4 -> 38 | H7: ="Booking on "&IF(Control!$B$9=Control!$C$4,DAY(Control!$B$9)&" "&CHOOSE(MONTH(Control!$B$9),"JAN","FEB","MAR","APR","MAY","JUN","JUL","AUG","SEP","OCT","NOV","DEC"),IF(MONTH(Control!$B$9)=MONTH(Control!$C$4),DAY(Control!$B$9)&"-"&DAY(Control!$C$4)&" "&CHOOSE(MONTH(Control!$C$4),"JAN","FEB","MAR","APR","MAY","JUN","JUL","AUG","SEP","OCT","NOV","DEC"),DAY(Control!$B$9)&" "&CHOOSE(MONTH(Control!$B$9),"JAN","FEB","MAR","APR","MAY","JUN","JUL","AUG","SEP","OCT","NOV","DEC")&"-"&DAY(Control!$C$4)&" "&CHOOSE(MONTH(Control!$C$4),"JAN","FEB","MAR","APR","MAY","JUN","JUL","AUG","SEP","OCT","NOV","DEC"))) -> Booking on 17-19 SEP | I7: =SUMIFS(BookingRaw!$C$2:$C$8000,BookingRaw!$A$2:$A$8000,"LCH27",BookingRaw!$B$2:$B$8000,">="&Control!$B$9,BookingRaw!$B$2:$B$8000,"<="&Control!$C$4) -> 0 | J7: =SUMIFS(BookingRaw!$D$2:$D$8000,BookingRaw!$A$2:$A$8000,"LCH27",BookingRaw!$B$2:$B$8000,">="&Control!$B$9,BookingRaw!$B$2:$B$8000,"<="&Control!$C$4) -> 13 | M7: BOOKING | N7: 22RE | O7: 45RE
B8: ="AV Balance till "&DAY(Control!$C$4)&" "&CHOOSE(MONTH(Control!$C$4),"JAN","FEB","MAR","APR","MAY","JUN","JUL","AUG","SEP","OCT","NOV","DEC") -> AV Balance till 19 SEP | C8: =C4-C5-C6-C7 -> 23 | D8: =D4-D5-D6-D7 -> 17 | H8: ="AV Balance till "&DAY(Control!$C$4)&" "&CHOOSE(MONTH(Control!$C$4),"JAN","FEB","MAR","APR","MAY","JUN","JUL","AUG","SEP","OCT","NOV","DEC") -> AV Balance till 19 SEP | I8: =I4-I5-I6-I7 -> 8 | J8: =J4-J5-J6-J7 -> 29 | M8: BC | N8: =C5+C6+C7+C9+C11 -> 15 | O8: =D5+D6+D7+D9+D11 -> 59
A9: =Control!$A$5 -> 39 | B9: ="Booking on "&IF(Control!$B5=Control!$C5,DAY(Control!$B5)&" "&CHOOSE(MONTH(Control!$B5),"JAN","FEB","MAR","APR","MAY","JUN","JUL","AUG","SEP","OCT","NOV","DEC"),IF(MONTH(Control!$B5)=MONTH(Control!$C5),DAY(Control!$B5)&"-"&DAY(Control!$C5)&" "&CHOOSE(MONTH(Control!$C5),"JAN","FEB","MAR","APR","MAY","JUN","JUL","AUG","SEP","OCT","NOV","DEC"),DAY(Control!$B5)&" "&CHOOSE(MONTH(Control!$B5),"JAN","FEB","MAR","APR","MAY","JUN","JUL","AUG","SEP","OCT","NOV","DEC")&"-"&DAY(Control!$C5)&" "&CHOOSE(MONTH(Control!$C5),"JAN","FEB","MAR","APR","MAY","JUN","JUL","AUG","SEP","OCT","NOV","DEC"))) -> Booking on 21-26 SEP | C9: =SUMIFS(BookingRaw!$C$2:$C$8000,BookingRaw!$A$2:$A$8000,"BKK27",BookingRaw!$B$2:$B$8000,">="&Control!$B5,BookingRaw!$B$2:$B$8000,"<="&Control!$C5) -> 5 | D9: =SUMIFS(BookingRaw!$D$2:$D$8000,BookingRaw!$A$2:$A$8000,"BKK27",BookingRaw!$B$2:$B$8000,">="&Control!$B5,BookingRaw!$B$2:$B$8000,"<="&Control!$C5) -> 25 | G9: =Control!$A$5 -> 39 | H9: ="Booking on "&IF(Control!$B5=Control!$C5,DAY(Control!$B5)&" "&CHOOSE(MONTH(Control!$B5),"JAN","FEB","MAR","APR","MAY","JUN","JUL","AUG","SEP","OCT","NOV","DEC"),IF(MONTH(Control!$B5)=MONTH(Control!$C5),DAY(Control!$B5)&"-"&DAY(Control!$C5)&" "&CHOOSE(MONTH(Control!$C5),"JAN","FEB","MAR","APR","MAY","JUN","JUL","AUG","SEP","OCT","NOV","DEC"),DAY(Control!$B5)&" "&CHOOSE(MONTH(Control!$B5),"JAN","FEB","MAR","APR","MAY","JUN","JUL","AUG","SEP","OCT","NOV","DEC")&"-"&DAY(Control!$C5)&" "&CHOOSE(MONTH(Control!$C5),"JAN","FEB","MAR","APR","MAY","JUN","JUL","AUG","SEP","OCT","NOV","DEC"))) -> Booking on 21-26 SEP | I9: =SUMIFS(BookingRaw!$C$2:$C$8000,BookingRaw!$A$2:$A$8000,"LCH27",BookingRaw!$B$2:$B$8000,">="&Control!$B5,BookingRaw!$B$2:$B$8000,"<="&Control!$C5) -> 2 | J9: =SUMIFS(BookingRaw!$D$2:$D$8000,BookingRaw!$A$2:$A$8000,"LCH27",BookingRaw!$B$2:$B$8000,">="&Control!$B5,BookingRaw!$B$2:$B$8000,"<="&Control!$C5) -> 18 | M9: HAST | N9: =I5+I6+I7+I9+I11 -> 2 | O9: =J5+J6+J7+J9+J11 -> 57
B10: ="AV Balance till "&DAY(Control!$C5)&" "&CHOOSE(MONTH(Control!$C5),"JAN","FEB","MAR","APR","MAY","JUN","JUL","AUG","SEP","OCT","NOV","DEC") -> AV Balance till 26 SEP | C10: =C8-C9 -> 18 | D10: =D8-D9 -> -8 | H10: ="AV Balance till "&DAY(Control!$C5)&" "&CHOOSE(MONTH(Control!$C5),"JAN","FEB","MAR","APR","MAY","JUN","JUL","AUG","SEP","OCT","NOV","DEC") -> AV Balance till 26 SEP | I10: =I8-I9 -> 6 | J10: =J8-J9 -> 11 | M10: TOTAL | N10: =SUM(N8:N9) -> 17 | O10: =SUM(O8:O9) -> 116
A11: =Control!$A$6 -> 40 | B11: ="Booking on "&IF(Control!$B6=Control!$C6,DAY(Control!$B6)&" "&CHOOSE(MONTH(Control!$B6),"JAN","FEB","MAR","APR","MAY","JUN","JUL","AUG","SEP","OCT","NOV","DEC"),IF(MONTH(Control!$B6)=MONTH(Control!$C6),DAY(Control!$B6)&"-"&DAY(Control!$C6)&" "&CHOOSE(MONTH(Control!$C6),"JAN","FEB","MAR","APR","MAY","JUN","JUL","AUG","SEP","OCT","NOV","DEC"),DAY(Control!$B6)&" "&CHOOSE(MONTH(Control!$B6),"JAN","FEB","MAR","APR","MAY","JUN","JUL","AUG","SEP","OCT","NOV","DEC")&"-"&DAY(Control!$C6)&" "&CHOOSE(MONTH(Control!$C6),"JAN","FEB","MAR","APR","MAY","JUN","JUL","AUG","SEP","OCT","NOV","DEC"))) -> Booking on 28 SEP-3 OCT | C11: =SUMIFS(BookingRaw!$C$2:$C$8000,BookingRaw!$A$2:$A$8000,"BKK27",BookingRaw!$B$2:$B$8000,">="&Control!$B6,BookingRaw!$B$2:$B$8000,"<="&Control!$C6) -> 2 | D11: =SUMIFS(BookingRaw!$D$2:$D$8000,BookingRaw!$A$2:$A$8000,"BKK27",BookingRaw!$B$2:$B$8000,">="&Control!$B6,BookingRaw!$B$2:$B$8000,"<="&Control!$C6) -> 1 | G11: =Control!$A$6 -> 40 | H11: ="Booking on "&IF(Control!$B6=Control!$C6,DAY(Control!$B6)&" "&CHOOSE(MONTH(Control!$B6),"JAN","FEB","MAR","APR","MAY","JUN","JUL","AUG","SEP","OCT","NOV","DEC"),IF(MONTH(Control!$B6)=MONTH(Control!$C6),DAY(Control!$B6)&"-"&DAY(Control!$C6)&" "&CHOOSE(MONTH(Control!$C6),"JAN","FEB","MAR","APR","MAY","JUN","JUL","AUG","SEP","OCT","NOV","DEC"),DAY(Control!$B6)&" "&CHOOSE(MONTH(Control!$B6),"JAN","FEB","MAR","APR","MAY","JUN","JUL","AUG","SEP","OCT","NOV","DEC")&"-"&DAY(Control!$C6)&" "&CHOOSE(MONTH(Control!$C6),"JAN","FEB","MAR","APR","MAY","JUN","JUL","AUG","SEP","OCT","NOV","DEC"))) -> Booking on 28 SEP-3 OCT | I11: =SUMIFS(BookingRaw!$C$2:$C$8000,BookingRaw!$A$2:$A$8000,"LCH27",BookingRaw!$B$2:$B$8000,">="&Control!$B6,BookingRaw!$B$2:$B$8000,"<="&Control!$C6) -> 0 | J11: =SUMIFS(BookingRaw!$D$2:$D$8000,BookingRaw!$A$2:$A$8000,"LCH27",BookingRaw!$B$2:$B$8000,">="&Control!$B6,BookingRaw!$B$2:$B$8000,"<="&Control!$C6) -> 5
B12: ="AV Balance till "&DAY(Control!$C6)&" "&CHOOSE(MONTH(Control!$C6),"JAN","FEB","MAR","APR","MAY","JUN","JUL","AUG","SEP","OCT","NOV","DEC") -> AV Balance till 3 OCT | C12: =C10-C11 -> 16 | D12: =D10-D11 -> -9 | H12: ="AV Balance till "&DAY(Control!$C6)&" "&CHOOSE(MONTH(Control!$C6),"JAN","FEB","MAR","APR","MAY","JUN","JUL","AUG","SEP","OCT","NOV","DEC") -> AV Balance till 3 OCT | I12: =I10-I11 -> 6 | J12: =J10-J11 -> 6 | M12: BALANCE | N12: 22RE | O12: 45RE
M13: BC | N13: =C12 -> 16 | O13: =D12 -> -9
M14: HAST | N14: =I12 -> 6 | O14: =J12 -> 6
B15: BKK / BC2 (BKK27) | H15: LCH / HAST (LCH27) | M15: TOTAL | N15: =SUM(N13:N14) -> 22 | O15: =SUM(O13:O14) -> -3
B16: YEAR BUILT 5 YEARS FOR DURIAN SEASON | C16: CARRIER | D16: DAIKIN | E16: THERMO KING | H16: YEAR BUILT 5 YEARS FOR DURIAN SEASON | I16: CARRIER | J16: DAIKIN | K16: THERMO KING
C17: 45RE | D17: 45RE | E17: 45RE | I17: 45RE | J17: 45RE | K17: 45RE
B18: 2026 | C18: 0 | D18: 0 | E18: 0 | H18: 2026 | I18: 0 | J18: 0 | K18: 0
B19: 2025 | C19: 8 | D19: 0 | E19: 0 | H19: 2025 | I19: 9 | J19: 0 | K19: 0
B20: 2024 | C20: 0 | D20: 0 | E20: 0 | H20: 2024 | I20: 0 | J20: 0 | K20: 0
B21: 2023 | C21: 3 | D21: 0 | E21: 0 | H21: 2023 | I21: 3 | J21: 0 | K21: 0
B22: 2022 | C22: 0 | D22: 0 | E22: 0 | H22: 2022 | I22: 0 | J22: 0 | K22: 0
B23: 2021 | C23: 17 | D23: 0 | E23: 0 | H23: 2021 | I23: 4 | J23: 0 | K23: 0
B24: TOTAL | C24: 28 | D24: 0 | E24: 0 | H24: TOTAL | I24: 16 | J24: 0 | K24: 0
D25: OVER 5 Y | E25: 22 | J25: OVER 5 Y | K25: 47
B28: BKK27 / BC2 — Stock by Built Year x Brand x Size | J28: LCH27 / HAST — Stock by Built Year x Brand x Size
B29: YEAR BUILT | C29: CARRIER | E29: DAIKIN | G29: THERMO KING | J29: YEAR BUILT | K29: CARRIER | M29: DAIKIN | O29: THERMO KING
C30: 20'RE | D30: 40'RH | E30: 20'RE | F30: 40'RH | G30: 20'RE | H30: 40'RH | K30: 20'RE | L30: 40'RH | M30: 20'RE | N30: 40'RH | O30: 20'RE | P30: 40'RH
B31: 2026 | J31: 2026
B32: 2025 | D32: 8 | E32: 4 | J32: 2025 | L32: 9 | M32: 1
B33: 2024 | J33: 2024
B34: 2023 | D34: 3 | J34: 2023 | L34: 3
B35: 2022 | J35: 2022
B36: 2021 | C36: 9 | D36: 17 | J36: 2021 | K36: 1 | L36: 4
B37: 2020 | C37: 2 | D37: 6 | J37: 2020 | L37: 8
B38: 2019 | C38: 2 | D38: 10 | J38: 2019 | L38: 13
B39: 2018 | C39: 1 | J39: 2018 | L39: 1
B40: 2017 | C40: 2 | D40: 3 | J40: 2017 | K40: 2 | L40: 1
B41: 2016 | C41: 2 | D41: 1 | J41: 2016 | K41: 1 | L41: 6
B42: 2015 | D42: 1 | E42: 1 | J42: 2015 | L42: 5
...
